Workbook

Sheet Dashboard
A1: NIS2 GAP Analysis
A2: Assessment Dashboard
A3: Fully formula-based. Values update as soon as an assessment sheet or the action plan changes. Rows scoped as "Central at HQ" or "Not Applicable" are excluded from coverage and scoring.
A5: Reporting date | B5: =TODAY()
A6: Requirements per entity | B6: 174
A8: Assessment Coverage by Entity
A9: Entity | B9: In Scope | C9: Assessed | D9: Coverage | E9: Average Score | F9: Work Packages | G9: "No" Answers | H9: Not Tested
A10: =Lists!$F$6 | B10: =COUNTIF(INDIRECT("'"&Lists!$O$6&"'!$I$6:$I$179"),"In Scope") | C10: =COUNTIFS(INDIRECT("'"&Lists!$O$6&"'!$I$6:$I$179"),"In Scope",INDIRECT("'"&Lists!$O$6&"'!$J$6:$J$179"),"?*") | D10: =IFERROR($C10/$B10,"") | E10: =IFERROR(AVERAGE(INDIRECT("'"&Lists!$O$6&"'!$N$6:$N$179")),"") | F10: =COUNTIF(INDIRECT("'"&Lists!$O$6&"'!$O$6:$O$179"),"Yes") | G10: =COUNTIF(INDIRECT("'"&Lists!$O$6&"'!$J$6:$J$179"),"No")+COUNTIF(INDIRECT("'"&Lists!$O$6&"'!$K$6:$K$179"),"No") | H10: =COUNTIF(INDIRECT("'"&Lists!$O$6&"'!$L$6:$L$179"),"Not Tested")
A11: =Lists!$F$7 | B11: =COUNTIF(INDIRECT("'"&Lists!$O$7&"'!$I$6:$I$179"),"In Scope") | C11: =COUNTIFS(INDIRECT("'"&Lists!$O$7&"'!$I$6:$I$179"),"In Scope",INDIRECT("'"&Lists!$O$7&"'!$J$6:$J$179"),"?*") | D11: =IFERROR($C11/$B11,"") | E11: =IFERROR(AVERAGE(INDIRECT("'"&Lists!$O$7&"'!$N$6:$N$179")),"") | F11: =COUNTIF(INDIRECT("'"&Lists!$O$7&"'!$O$6:$O$179"),"Yes") | G11: =COUNTIF(INDIRECT("'"&Lists!$O$7&"'!$J$6:$J$179"),"No")+COUNTIF(INDIRECT("'"&Lists!$O$7&"'!$K$6:$K$179"),"No") | H11: =COUNTIF(INDIRECT("'"&Lists!$O$7&"'!$L$6:$L$179"),"Not Tested")
A12: =Lists!$F$8 | B12: =COUNTIF(INDIRECT("'"&Lists!$O$8&"'!$I$6:$I$179"),"In Scope") | C12: =COUNTIFS(INDIRECT("'"&Lists!$O$8&"'!$I$6:$I$179"),"In Scope",INDIRECT("'"&Lists!$O$8&"'!$J$6:$J$179"),"?*") | D12: =IFERROR($C12/$B12,"") | E12: =IFERROR(AVERAGE(INDIRECT("'"&Lists!$O$8&"'!$N$6:$N$179")),"") | F12: =COUNTIF(INDIRECT("'"&Lists!$O$8&"'!$O$6:$O$179"),"Yes") | G12: =COUNTIF(INDIRECT("'"&Lists!$O$8&"'!$J$6:$J$179"),"No")+COUNTIF(INDIRECT("'"&Lists!$O$8&"'!$K$6:$K$179"),"No") | H12: =COUNTIF(INDIRECT("'"&Lists!$O$8&"'!$L$6:$L$179"),"Not Tested")
A13: =Lists!$F$9 | B13: =COUNTIF(INDIRECT("'"&Lists!$O$9&"'!$I$6:$I$179"),"In Scope") | C13: =COUNTIFS(INDIRECT("'"&Lists!$O$9&"'!$I$6:$I$179"),"In Scope",INDIRECT("'"&Lists!$O$9&"'!$J$6:$J$179"),"?*") | D13: =IFERROR($C13/$B13,"") | E13: =IFERROR(AVERAGE(INDIRECT("'"&Lists!$O$9&"'!$N$6:$N$179")),"") | F13: =COUNTIF(INDIRECT("'"&Lists!$O$9&"'!$O$6:$O$179"),"Yes") | G13: =COUNTIF(INDIRECT("'"&Lists!$O$9&"'!$J$6:$J$179"),"No")+COUNTIF(INDIRECT("'"&Lists!$O$9&"'!$K$6:$K$179"),"No") | H13: =COUNTIF(INDIRECT("'"&Lists!$O$9&"'!$L$6:$L$179"),"Not Tested")
A14: All entities | B14: =SUM($B$10:$B$13) | C14: =SUM($C$10:$C$13) | D14: =IFERROR($C14/$B14,"") | E14: =IFERROR(AVERAGE($E$10:$E$13),"") | F14: =SUM($F$10:$F$13) | G14: =SUM($G$10:$G$13) | H14: =SUM($H$10:$H$13)
A16: Average Score by Chapter
A17: Chapter | B17: Target | C17: =Lists!$F$6 | D17: =Lists!$F$7 | E17: =Lists!$F$8 | F17: =Lists!$F$9 | G17: Group Average | H17: Gap to Target | I17: Work Packages
A18: 1 Policy on the security of network and information systems | B18: 0.75 | C18: =IFERROR(AVERAGEIFS(INDIRECT("'"&Lists!$O$6&"'!$N$6:$N$179"),INDIRECT("'"&Lists!$O$6&"'!$B$6:$B$179"),$A18),"") | D18: =IFERROR(AVERAGEIFS(INDIRECT("'"&Lists!$O$7&"'!$N$6:$N$179"),INDIRECT("'"&Lists!$O$7&"'!$B$6:$B$179"),$A18),"") | E18: =IFERROR(AVERAGEIFS(INDIRECT("'"&Lists!$O$8&"'!$N$6:$N$179"),INDIRECT("'"&Lists!$O$8&"'!$B$6:$B$179"),$A18),"") | F18: =IFERROR(AVERAGEIFS(INDIRECT("'"&Lists!$O$9&"'!$N$6:$N$179"),INDIRECT("'"&Lists!$O$9&"'!$B$6:$B$179"),$A18),"") | G18: =IFERROR(AVERAGE($C18:$F18),"") | H18: =IF($G18="","",MAX(0,$B18-$G18)) | I18: =COUNTIFS(INDIRECT("'"&Lists!$O$6&"'!$O$6:$O$179"),"Yes",INDIRECT("'"&Lists!$O$6&"'!$B$6:$B$179"),$A18)+COUNTIFS(INDIRECT("'"&Lists!$O$7&"'!$O$6:$O$179"),"Yes",INDIRECT("'"&Lists!$O$7&"'!$B$6:$B$179"),$A18)+COUNTIFS(INDIRECT("'"&Lists!$O$8&"'!$O$6:$O$179"),"Yes",INDIRECT("'"&Lists!$O$8&"'!$B$6:$B$179"),$A18)+COUNTIFS(INDIRECT("'"&Lists!$O$9&"'!$O$6:$O$179"),"Yes",INDIRECT("'"&Lists!$O$9&"'!$B$6:$B$179"),$A18)
A19: 2 Risk management policy | B19: 0.75 | C19: =IFERROR(AVERAGEIFS(INDIRECT("'"&Lists!$O$6&"'!$N$6:$N$179"),INDIRECT("'"&Lists!$O$6&"'!$B$6:$B$179"),$A19),"") | D19: =IFERROR(AVERAGEIFS(INDIRECT("'"&Lists!$O$7&"'!$N$6:$N$179"),INDIRECT("'"&Lists!$O$7&"'!$B$6:$B$179"),$A19),"") | E19: =IFERROR(AVERAGEIFS(INDIRECT("'"&Lists!$O$8&"'!$N$6:$N$179"),INDIRECT("'"&Lists!$O$8&"'!$B$6:$B$179"),$A19),"") | F19: =IFERROR(AVERAGEIFS(INDIRECT("'"&Lists!$O$9&"'!$N$6:$N$179"),INDIRECT("'"&Lists!$O$9&"'!$B$6:$B$179"),$A19),"") | G19: =IFERROR(AVERAGE($C19:$F19),"") | H19: =IF($G19="","",MAX(0,$B19-$G19)) | I19: =COUNTIFS(INDIRECT("'"&Lists!$O$6&"'!$O$6:$O$179"),"Yes",INDIRECT("'"&Lists!$O$6&"'!$B$6:$B$179"),$A19)+COUNTIFS(INDIRECT("'"&Lists!$O$7&"'!$O$6:$O$179"),"Yes",INDIRECT("'"&Lists!$O$7&"'!$B$6:$B$179"),$A19)+COUNTIFS(INDIRECT("'"&Lists!$O$8&"'!$O$6:$O$179"),"Yes",INDIRECT("'"&Lists!$O$8&"'!$B$6:$B$179"),$A19)+COUNTIFS(INDIRECT("'"&Lists!$O$9&"'!$O$6:$O$179"),"Yes",INDIRECT("'"&Lists!$O$9&"'!$B$6:$B$179"),$A19)
A20: 3 Incident handling | B20: 0.75 | C20: =IFERROR(AVERAGEIFS(INDIRECT("'"&Lists!$O$6&"'!$N$6:$N$179"),INDIRECT("'"&Lists!$O$6&"'!$B$6:$B$179"),$A20),"") | D20: =IFERROR(AVERAGEIFS(INDIRECT("'"&Lists!$O$7&"'!$N$6:$N$179"),INDIRECT("'"&Lists!$O$7&"'!$B$6:$B$179"),$A20),"") | E20: =IFERROR(AVERAGEIFS(INDIRECT("'"&Lists!$O$8&"'!$N$6:$N$179"),INDIRECT("'"&Lists!$O$8&"'!$B$6:$B$179"),$A20),"") | F20: =IFERROR(AVERAGEIFS(INDIRECT("'"&Lists!$O$9&"'!$N$6:$N$179"),INDIRECT("'"&Lists!$O$9&"'!$B$6:$B$179"),$A20),"") | G20: =IFERROR(AVERAGE($C20:$F20),"") | H20: =IF($G20="","",MAX(0,$B20-$G20)) | I20: =COUNTIFS(INDIRECT("'"&Lists!$O$6&"'!$O$6:$O$179"),"Yes",INDIRECT("'"&Lists!$O$6&"'!$B$6:$B$179"),$A20)+COUNTIFS(INDIRECT("'"&Lists!$O$7&"'!$O$6:$O$179"),"Yes",INDIRECT("'"&Lists!$O$7&"'!$B$6:$B$179"),$A20)+COUNTIFS(INDIRECT("'"&Lists!$O$8&"'!$O$6:$O$179"),"Yes",INDIRECT("'"&Lists!$O$8&"'!$B$6:$B$179"),$A20)+COUNTIFS(INDIRECT("'"&Lists!$O$9&"'!$O$6:$O$179"),"Yes",INDIRECT("'"&Lists!$O$9&"'!$B$6:$B$179"),$A20)
A21: 4 Business continuity and crisis management | B21: 0.75 | C21: =IFERROR(AVERAGEIFS(INDIRECT("'"&Lists!$O$6&"'!$N$6:$N$179"),INDIRECT("'"&Lists!$O$6&"'!$B$6:$B$179"),$A21),"") | D21: =IFERROR(AVERAGEIFS(INDIRECT("'"&Lists!$O$7&"'!$N$6:$N$179"),INDIRECT("'"&Lists!$O$7&"'!$B$6:$B$179"),$A21),"") | E21: =IFERROR(AVERAGEIFS(INDIRECT("'"&Lists!$O$8&"'!$N$6:$N$179"),INDIRECT("'"&Lists!$O$8&"'!$B$6:$B$179"),$A21),"") | F21: =IFERROR(AVERAGEIFS(INDIRECT("'"&Lists!$O$9&"'!$N$6:$N$179"),INDIRECT("'"&Lists!$O$9&"'!$B$6:$B$179"),$A21),"") | G21: =IFERROR(AVERAGE($C21:$F21),"") | H21: =IF($G21="","",MAX(0,$B21-$G21)) | I21: =COUNTIFS(INDIRECT("'"&Lists!$O$6&"'!$O$6:$O$179"),"Yes",INDIRECT("'"&Lists!$O$6&"'!$B$6:$B$179"),$A21)+COUNTIFS(INDIRECT("'"&Lists!$O$7&"'!$O$6:$O$179"),"Yes",INDIRECT("'"&Lists!$O$7&"'!$B$6:$B$179"),$A21)+COUNTIFS(INDIRECT("'"&Lists!$O$8&"'!$O$6:$O$179"),"Yes",INDIRECT("'"&Lists!$O$8&"'!$B$6:$B$179"),$A21)+COUNTIFS(INDIRECT("'"&Lists!$O$9&"'!$O$6:$O$179"),"Yes",INDIRECT("'"&Lists!$O$9&"'!$B$6:$B$179"),$A21)
A22: 5 Supply chain security | B22: 0.75 | C22: =IFERROR(AVERAGEIFS(INDIRECT("'"&Lists!$O$6&"'!$N$6:$N$179"),INDIRECT("'"&Lists!$O$6&"'!$B$6:$B$179"),$A22),"") | D22: =IFERROR(AVERAGEIFS(INDIRECT("'"&Lists!$O$7&"'!$N$6:$N$179"),INDIRECT("'"&Lists!$O$7&"'!$B$6:$B$179"),$A22),"") | E22: =IFERROR(AVERAGEIFS(INDIRECT("'"&Lists!$O$8&"'!$N$6:$N$179"),INDIRECT("'"&Lists!$O$8&"'!$B$6:$B$179"),$A22),"") | F22: =IFERROR(AVERAGEIFS(INDIRECT("'"&Lists!$O$9&"'!$N$6:$N$179"),INDIRECT("'"&Lists!$O$9&"'!$B$6:$B$179"),$A22),"") | G22: =IFERROR(AVERAGE($C22:$F22),"") | H22: =IF($G22="","",MAX(0,$B22-$G22)) | I22: =COUNTIFS(INDIRECT("'"&Lists!$O$6&"'!$O$6:$O$179"),"Yes",INDIRECT("'"&Lists!$O$6&"'!$B$6:$B$179"),$A22)+COUNTIFS(INDIRECT("'"&Lists!$O$7&"'!$O$6:$O$179"),"Yes",INDIRECT("'"&Lists!$O$7&"'!$B$6:$B$179"),$A22)+COUNTIFS(INDIRECT("'"&Lists!$O$8&"'!$O$6:$O$179"),"Yes",INDIRECT("'"&Lists!$O$8&"'!$B$6:$B$179"),$A22)+COUNTIFS(INDIRECT("'"&Lists!$O$9&"'!$O$6:$O$179"),"Yes",INDIRECT("'"&Lists!$O$9&"'!$B$6:$B$179"),$A22)
A23: 6 Security in network and information systems acquisition, development and maintenance | B23: 0.75 | C23: =IFERROR(AVERAGEIFS(INDIRECT("'"&Lists!$O$6&"'!$N$6:$N$179"),INDIRECT("'"&Lists!$O$6&"'!$B$6:$B$179"),$A23),"") | D23: =IFERROR(AVERAGEIFS(INDIRECT("'"&Lists!$O$7&"'!$N$6:$N$179"),INDIRECT("'"&Lists!$O$7&"'!$B$6:$B$179"),$A23),"") | E23: =IFERROR(AVERAGEIFS(INDIRECT("'"&Lists!$O$8&"'!$N$6:$N$179"),INDIRECT("'"&Lists!$O$8&"'!$B$6:$B$179"),$A23),"") | F23: =IFERROR(AVERAGEIFS(INDIRECT("'"&Lists!$O$9&"'!$N$6:$N$179"),INDIRECT("'"&Lists!$O$9&"'!$B$6:$B$179"),$A23),"") | G23: =IFERROR(AVERAGE($C23:$F23),"") | H23: =IF($G23="","",MAX(0,$B23-$G23)) | I23: =COUNTIFS(INDIRECT("'"&Lists!$O$6&"'!$O$6:$O$179"),"Yes",INDIRECT("'"&Lists!$O$6&"'!$B$6:$B$179"),$A23)+COUNTIFS(INDIRECT("'"&Lists!$O$7&"'!$O$6:$O$179"),"Yes",INDIRECT("'"&Lists!$O$7&"'!$B$6:$B$179"),$A23)+COUNTIFS(INDIRECT("'"&Lists!$O$8&"'!$O$6:$O$179"),"Yes",INDIRECT("'"&Lists!$O$8&"'!$B$6:$B$179"),$A23)+COUNTIFS(INDIRECT("'"&Lists!$O$9&"'!$O$6:$O$179"),"Yes",INDIRECT("'"&Lists!$O$9&"'!$B$6:$B$179"),$A23)
A24: 7 Policies and procedures to assess the effectiveness of cybersecurity risk-management measures | B24: 0.75 | C24: =IFERROR(AVERAGEIFS(INDIRECT("'"&Lists!$O$6&"'!$N$6:$N$179"),INDIRECT("'"&Lists!$O$6&"'!$B$6:$B$179"),$A24),"") | D24: =IFERROR(AVERAGEIFS(INDIRECT("'"&Lists!$O$7&"'!$N$6:$N$179"),INDIRECT("'"&Lists!$O$7&"'!$B$6:$B$179"),$A24),"") | E24: =IFERROR(AVERAGEIFS(INDIRECT("'"&Lists!$O$8&"'!$N$6:$N$179"),INDIRECT("'"&Lists!$O$8&"'!$B$6:$B$179"),$A24),"") | F24: =IFERROR(AVERAGEIFS(INDIRECT("'"&Lists!$O$9&"'!$N$6:$N$179"),INDIRECT("'"&Lists!$O$9&"'!$B$6:$B$179"),$A24),"") | G24: =IFERROR(AVERAGE($C24:$F24),"") | H24: =IF($G24="","",MAX(0,$B24-$G24)) | I24: =COUNTIFS(INDIRECT("'"&Lists!$O$6&"'!$O$6:$O$179"),"Yes",INDIRECT("'"&Lists!$O$6&"'!$B$6:$B$179"),$A24)+COUNTIFS(INDIRECT("'"&Lists!$O$7&"'!$O$6:$O$179"),"Yes",INDIRECT("'"&Lists!$O$7&"'!$B$6:$B$179"),$A24)+COUNTIFS(INDIRECT("'"&Lists!$O$8&"'!$O$6:$O$179"),"Yes",INDIRECT("'"&Lists!$O$8&"'!$B$6:$B$179"),$A24)+COUNTIFS(INDIRECT("'"&Lists!$O$9&"'!$O$6:$O$179"),"Yes",INDIRECT("'"&Lists!$O$9&"'!$B$6:$B$179"),$A24)
A25: 8 Basic cyber hygiene practices and security training | B25: 0.75 | C25: =IFERROR(AVERAGEIFS(INDIRECT("'"&Lists!$O$6&"'!$N$6:$N$179"),INDIRECT("'"&Lists!$O$6&"'!$B$6:$B$179"),$A25),"") | D25: =IFERROR(AVERAGEIFS(INDIRECT("'"&Lists!$O$7&"'!$N$6:$N$179"),INDIRECT("'"&Lists!$O$7&"'!$B$6:$B$179"),$A25),"") | E25: =IFERROR(AVERAGEIFS(INDIRECT("'"&Lists!$O$8&"'!$N$6:$N$179"),INDIRECT("'"&Lists!$O$8&"'!$B$6:$B$179"),$A25),"") | F25: =IFERROR(AVERAGEIFS(INDIRECT("'"&Lists!$O$9&"'!$N$6:$N$179"),INDIRECT("'"&Lists!$O$9&"'!$B$6:$B$179"),$A25),"") | G25: =IFERROR(AVERAGE($C25:$F25),"") | H25: =IF($G25="","",MAX(0,$B25-$G25)) | I25: =COUNTIFS(INDIRECT("'"&Lists!$O$6&"'!$O$6:$O$179"),"Yes",INDIRECT("'"&Lists!$O$6&"'!$B$6:$B$179"),$A25)+COUNTIFS(INDIRECT("'"&Lists!$O$7&"'!$O$6:$O$179"),"Yes",INDIRECT("'"&Lists!$O$7&"'!$B$6:$B$179"),$A25)+COUNTIFS(INDIRECT("'"&Lists!$O$8&"'!$O$6:$O$179"),"Yes",INDIRECT("'"&Lists!$O$8&"'!$B$6:$B$179"),$A25)+COUNTIFS(INDIRECT("'"&Lists!$O$9&"'!$O$6:$O$179"),"Yes",INDIRECT("'"&Lists!$O$9&"'!$B$6:$B$179"),$A25)
A26: 9 Cryptography | B26: 0.75 | C26: =IFERROR(AVERAGEIFS(INDIRECT("'"&Lists!$O$6&"'!$N$6:$N$179"),INDIRECT("'"&Lists!$O$6&"'!$B$6:$B$179"),$A26),"") | D26: =IFERROR(AVERAGEIFS(INDIRECT("'"&Lists!$O$7&"'!$N$6:$N$179"),INDIRECT("'"&Lists!$O$7&"'!$B$6:$B$179"),$A26),"") | E26: =IFERROR(AVERAGEIFS(INDIRECT("'"&Lists!$O$8&"'!$N$6:$N$179"),INDIRECT("'"&Lists!$O$8&"'!$B$6:$B$179"),$A26),"") | F26: =IFERROR(AVERAGEIFS(INDIRECT("'"&Lists!$O$9&"'!$N$6:$N$179"),INDIRECT("'"&Lists!$O$9&"'!$B$6:$B$179"),$A26),"") | G26: =IFERROR(AVERAGE($C26:$F26),"") | H26: =IF($G26="","",MAX(0,$B26-$G26)) | I26: =COUNTIFS(INDIRECT("'"&Lists!$O$6&"'!$O$6:$O$179"),"Yes",INDIRECT("'"&Lists!$O$6&"'!$B$6:$B$179"),$A26)+COUNTIFS(INDIRECT("'"&Lists!$O$7&"'!$O$6:$O$179"),"Yes",INDIRECT("'"&Lists!$O$7&"'!$B$6:$B$179"),$A26)+COUNTIFS(INDIRECT("'"&Lists!$O$8&"'!$O$6:$O$179"),"Yes",INDIRECT("'"&Lists!$O$8&"'!$B$6:$B$179"),$A26)+COUNTIFS(INDIRECT("'"&Lists!$O$9&"'!$O$6:$O$179"),"Yes",INDIRECT("'"&Lists!$O$9&"'!$B$6:$B$179"),$A26)
A27: 10 Human resources security | B27: 0.75 | C27: =IFERROR(AVERAGEIFS(INDIRECT("'"&Lists!$O$6&"'!$N$6:$N$179"),INDIRECT("'"&Lists!$O$6&"'!$B$6:$B$179"),$A27),"") | D27: =IFERROR(AVERAGEIFS(INDIRECT("'"&Lists!$O$7&"'!$N$6:$N$179"),INDIRECT("'"&Lists!$O$7&"'!$B$6:$B$179"),$A27),"") | E27: =IFERROR(AVERAGEIFS(INDIRECT("'"&Lists!$O$8&"'!$N$6:$N$179"),INDIRECT("'"&Lists!$O$8&"'!$B$6:$B$179"),$A27),"") | F27: =IFERROR(AVERAGEIFS(INDIRECT("'"&Lists!$O$9&"'!$N$6:$N$179"),INDIRECT("'"&Lists!$O$9&"'!$B$6:$B$179"),$A27),"") | G27: =IFERROR(AVERAGE($C27:$F27),"") | H27: =IF($G27="","",MAX(0,$B27-$G27)) | I27: =COUNTIFS(INDIRECT("'"&Lists!$O$6&"'!$O$6:$O$179"),"Yes",INDIRECT("'"&Lists!$O$6&"'!$B$6:$B$179"),$A27)+COUNTIFS(INDIRECT("'"&Lists!$O$7&"'!$O$6:$O$179"),"Yes",INDIRECT("'"&Lists!$O$7&"'!$B$6:$B$179"),$A27)+COUNTIFS(INDIRECT("'"&Lists!$O$8&"'!$O$6:$O$179"),"Yes",INDIRECT("'"&Lists!$O$8&"'!$B$6:$B$179"),$A27)+COUNTIFS(INDIRECT("'"&Lists!$O$9&"'!$O$6:$O$179"),"Yes",INDIRECT("'"&Lists!$O$9&"'!$B$6:$B$179"),$A27)
A28: 11 Access control | B28: 0.75 | C28: =IFERROR(AVERAGEIFS(INDIRECT("'"&Lists!$O$6&"'!$N$6:$N$179"),INDIRECT("'"&Lists!$O$6&"'!$B$6:$B$179"),$A28),"") | D28: =IFERROR(AVERAGEIFS(INDIRECT("'"&Lists!$O$7&"'!$N$6:$N$179"),INDIRECT("'"&Lists!$O$7&"'!$B$6:$B$179"),$A28),"") | E28: =IFERROR(AVERAGEIFS(INDIRECT("'"&Lists!$O$8&"'!$N$6:$N$179"),INDIRECT("'"&Lists!$O$8&"'!$B$6:$B$179"),$A28),"") | F28: =IFERROR(AVERAGEIFS(INDIRECT("'"&Lists!$O$9&"'!$N$6:$N$179"),INDIRECT("'"&Lists!$O$9&"'!$B$6:$B$179"),$A28),"") | G28: =IFERROR(AVERAGE($C28:$F28),"") | H28: =IF($G28="","",MAX(0,$B28-$G28)) | I28: =COUNTIFS(INDIRECT("'"&Lists!$O$6&"'!$O$6:$O$179"),"Yes",INDIRECT("'"&Lists!$O$6&"'!$B$6:$B$179"),$A28)+COUNTIFS(INDIRECT("'"&Lists!$O$7&"'!$O$6:$O$179"),"Yes",INDIRECT("'"&Lists!$O$7&"'!$B$6:$B$179"),$A28)+COUNTIFS(INDIRECT("'"&Lists!$O$8&"'!$O$6:$O$179"),"Yes",INDIRECT("'"&Lists!$O$8&"'!$B$6:$B$179"),$A28)+COUNTIFS(INDIRECT("'"&Lists!$O$9&"'!$O$6:$O$179"),"Yes",INDIRECT("'"&Lists!$O$9&"'!$B$6:$B$179"),$A28)
A29: 12 Asset management | B29: 0.75 | C29: =IFERROR(AVERAGEIFS(INDIRECT("'"&Lists!$O$6&"'!$N$6:$N$179"),INDIRECT("'"&Lists!$O$6&"'!$B$6:$B$179"),$A29),"") | D29: =IFERROR(AVERAGEIFS(INDIRECT("'"&Lists!$O$7&"'!$N$6:$N$179"),INDIRECT("'"&Lists!$O$7&"'!$B$6:$B$179"),$A29),"") | E29: =IFERROR(AVERAGEIFS(INDIRECT("'"&Lists!$O$8&"'!$N$6:$N$179"),INDIRECT("'"&Lists!$O$8&"'!$B$6:$B$179"),$A29),"") | F29: =IFERROR(AVERAGEIFS(INDIRECT("'"&Lists!$O$9&"'!$N$6:$N$179"),INDIRECT("'"&Lists!$O$9&"'!$B$6:$B$179"),$A29),"") | G29: =IFERROR(AVERAGE($C29:$F29),"") | H29: =IF($G29="","",MAX(0,$B29-$G29)) | I29: =COUNTIFS(INDIRECT("'"&Lists!$O$6&"'!$O$6:$O$179"),"Yes",INDIRECT("'"&Lists!$O$6&"'!$B$6:$B$179"),$A29)+COUNTIFS(INDIRECT("'"&Lists!$O$7&"'!$O$6:$O$179"),"Yes",INDIRECT("'"&Lists!$O$7&"'!$B$6:$B$179"),$A29)+COUNTIFS(INDIRECT("'"&Lists!$O$8&"'!$O$6:$O$179"),"Yes",INDIRECT("'"&Lists!$O$8&"'!$B$6:$B$179"),$A29)+COUNTIFS(INDIRECT("'"&Lists!$O$9&"'!$O$6:$O$179"),"Yes",INDIRECT("'"&Lists!$O$9&"'!$B$6:$B$179"),$A29)
... A34: 17 OT and production security | B34: 0.75 | C34: =IFERROR(AVERAGEIFS(INDIRECT("'"&Lists!$O$6&"'!$N$6:$N$179"),INDIRECT("'"&Lists!$O$6&"'!$B$6:$B$179"),$A34),"") | D34: =IFERROR(AVERAGEIFS(INDIRECT("'"&Lists!$O$7&"'!$N$6:$N$179"),INDIRECT("'"&Lists!$O$7&"'!$B$6:$B$179"),$A34),"") | E34: =IFERROR(AVERAGEIFS(INDIRECT("'"&Lists!$O$8&"'!$N$6:$N$179"),INDIRECT("'"&Lists!$O$8&"'!$B$6:$B$179"),$A34),"") | F34: =IFERROR(AVERAGEIFS(INDIRECT("'"&Lists!$O$9&"'!$N$6:$N$179"),INDIRECT("'"&Lists!$O$9&"'!$B$6:$B$179"),$A34),"") | G34: =IFERROR(AVERAGE($C34:$F34),"") | H34: =IF($G34="","",MAX(0,$B34-$G34)) | I34: =COUNTIFS(INDIRECT("'"&Lists!$O$6&"'!$O$6:$O$179"),"Yes",INDIRECT("'"&Lists!$O$6&"'!$B$6:$B$179"),$A34)+COUNTIFS(INDIRECT("'"&Lists!$O$7&"'!$O$6:$O$179"),"Yes",INDIRECT("'"&Lists!$O$7&"'!$B$6:$B$179"),$A34)+COUNTIFS(INDIRECT("'"&Lists!$O$8&"'!$O$6:$O$179"),"Yes",INDIRECT("'"&Lists!$O$8&"'!$B$6:$B$179"),$A34)+COUNTIFS(INDIRECT("'"&Lists!$O$9&"'!$O$6:$O$179"),"Yes",INDIRECT("'"&Lists!$O$9&"'!$B$6:$B$179"),$A34)
A36: Answer Distribution (Implemented)
A37: Entity | B37: Yes | C37: Partial | D37: No | E37: Not assessed
A38: =Lists!$F$6 | B38: =COUNTIFS(INDIRECT("'"&Lists!$O$6&"'!$I$6:$I$179"),"In Scope",INDIRECT("'"&Lists!$O$6&"'!$J$6:$J$179"),"Yes") | C38: =COUNTIFS(INDIRECT("'"&Lists!$O$6&"'!$I$6:$I$179"),"In Scope",INDIRECT("'"&Lists!$O$6&"'!$J$6:$J$179"),"Partial") | D38: =COUNTIFS(INDIRECT("'"&Lists!$O$6&"'!$I$6:$I$179"),"In Scope",INDIRECT("'"&Lists!$O$6&"'!$J$6:$J$179"),"No") | E38: =COUNTIF(INDIRECT("'"&Lists!$O$6&"'!$I$6:$I$179"),"In Scope")-SUM($B38:$D38)
A39: =Lists!$F$7 | B39: =COUNTIFS(INDIRECT("'"&Lists!$O$7&"'!$I$6:$I$179"),"In Scope",INDIRECT("'"&Lists!$O$7&"'!$J$6:$J$179"),"Yes") | C39: =COUNTIFS(INDIRECT("'"&Lists!$O$7&"'!$I$6:$I$179"),"In Scope",INDIRECT("'"&Lists!$O$7&"'!$J$6:$J$179"),"Partial") | D39: =COUNTIFS(INDIRECT("'"&Lists!$O$7&"'!$I$6:$I$179"),"In Scope",INDIRECT("'"&Lists!$O$7&"'!$J$6:$J$179"),"No") | E39: =COUNTIF(INDIRECT("'"&Lists!$O$7&"'!$I$6:$I$179"),"In Scope")-SUM($B39:$D39)
A40: =Lists!$F$8 | B40: =COUNTIFS(INDIRECT("'"&Lists!$O$8&"'!$I$6:$I$179"),"In Scope",INDIRECT("'"&Lists!$O$8&"'!$J$6:$J$179"),"Yes") | C40: =COUNTIFS(INDIRECT("'"&Lists!$O$8&"'!$I$6:$I$179"),"In Scope",INDIRECT("'"&Lists!$O$8&"'!$J$6:$J$179"),"Partial") | D40: =COUNTIFS(INDIRECT("'"&Lists!$O$8&"'!$I$6:$I$179"),"In Scope",INDIRECT("'"&Lists!$O$8&"'!$J$6:$J$179"),"No") | E40: =COUNTIF(INDIRECT("'"&Lists!$O$8&"'!$I$6:$I$179"),"In Scope")-SUM($B40:$D40)
A41: =Lists!$F$9 | B41: =COUNTIFS(INDIRECT("'"&Lists!$O$9&"'!$I$6:$I$179"),"In Scope",INDIRECT("'"&Lists!$O$9&"'!$J$6:$J$179"),"Yes") | C41: =COUNTIFS(INDIRECT("'"&Lists!$O$9&"'!$I$6:$I$179"),"In Scope",INDIRECT("'"&Lists!$O$9&"'!$J$6:$J$179"),"Partial") | D41: =COUNTIFS(INDIRECT("'"&Lists!$O$9&"'!$I$6:$I$179"),"In Scope",INDIRECT("'"&Lists!$O$9&"'!$J$6:$J$179"),"No") | E41: =COUNTIF(INDIRECT("'"&Lists!$O$9&"'!$I$6:$I$179"),"In Scope")-SUM($B41:$D41)
A44: Action Plan | D44: Scoring Model
A45: Indicator | B45: Value | D45: Answer | E45: Score | F45: Note
A46: Work packages in plan | B46: =COUNTIF('Action Plan'!$G$6:$G$205,"?*") | D46: Yes / Effective | E46: 1 | F46: Full credit
A47: High priority | B47: =COUNTIFS('Action Plan'!$G$6:$G$205,"?*",'Action Plan'!$H$6:$H$205,"High") | D47: Partial | E47: 0.5 | F47: Half credit
A48: Medium priority | B48: =COUNTIFS('Action Plan'!$G$6:$G$205,"?*",'Action Plan'!$H$6:$H$205,"Medium") | D48: Not Tested | E48: 0.25 | F48: Implemented but unverified
A49: Low priority | B49: =COUNTIFS('Action Plan'!$G$6:$G$205,"?*",'Action Plan'!$H$6:$H$205,"Low") | D49: No / Ineffective | E49: 0 | F49: No credit
A50: Not started | B50: =COUNTIFS('Action Plan'!$G$6:$G$205,"?*",'Action Plan'!$M$6:$M$205,"Not Started") | D50: N/A | E50: - | F50: Excluded from the average
...

Sheet Lists
A1: NIS2 GAP Analysis
A2: Master Data and Picklists
A3: Single source for every drop-down in this workbook. Add values at the end of a column and extend the named range under Formulas > Name Manager.
A5: Implemented / Documented | B5: Effectiveness | C5: Effort | D5: Priority | E5: Status | F5: Entity | G5: Scope | H5: Yes / No | J5: Scoring model | M5: Chapter | O5: Sheet name | P5: Finding ID prefix | Q5: Check | S5: Responsible
A6: Yes | B6: Effective | C6: Low | D6: High | E6: Not Started | G6: In Scope | H6: Yes | J6: Answer | K6: Score | M6: 1 Policy on the security of network and information systems | S6: Information Security Officer | U6: Blue cells are maintained here only. Column F is the display name used on the Dashboard, the entity sheets and the Action Plan drop-down. Column O must match the actual tab name; if you rename a tab, update it here and column Q switches back to OK.
A7: Partial | B7: Partial | C7: Medium | D7: Medium | E7: In Progress | G7: Central at HQ | H7: No | J7: Yes / Effective | K7: 1 | M7: 2 Risk management policy | S7: IT Coordinator
A8: No | B8: Not Tested | C8: High | D8: Low | E8: Completed | G8: Not Applicable | J8: Partial | K8: 0.5 | M8: 3 Incident handling | S8: Central IT
A9: N/A | B9: Ineffective | E9: Blocked | J9: Not Tested | K9: 0.25 | M9: 4 Business continuity and crisis management | S9: Local IT
B10: N/A | E10: Deferred | J10: No / Ineffective | K10: 0 | M10: 5 Supply chain security | S10: MSP+IT
J11: N/A | K11: excluded | M11: 6 Security in network and information systems acquisition, development and maintenance | S11: Data Protection Officer
M12: 7 Policies and procedures to assess the effectiveness of cybersecurity risk-management measures | S12: HR
M13: 8 Basic cyber hygiene practices and security training | S13: IT Procurement
M14: 9 Cryptography | S14: OT
M15: 10 Human resources security | S15: Management Board
M16: 11 Access control | S16: German External Adviser
M17: 12 Asset management | S17: Dutch External Adviser
M18: 13 Environmental and physical security | S18: Local Contact
M19: 14 Incident reporting to the competent authority
M20: 15 Registration | S20: Replace these roles with the actual names of the people responsible, or mix both.
M21: 16 Management responsibility
M22: 17 OT and production security

Sheet Requirements
A1: NIS2 GAP Analysis
A2: Requirement catalogue
A3: Columns A to H are reference content, columns I to M and P to T are for the assessment, shaded columns are calculated. Set Scope to "Central at HQ" or "Not Applicable" to exclude a row from scoring. | J3: ="Assessed "&COUNTIFS($I$6:$I$179,"In Scope",$J$6:$J$179,"?*")&" / "&COUNTIF($I$6:$I$179,"In Scope")&" | Average score "&IF(COUNT($N$6:$N$179)=0,"-",TEXT(AVERAGE($N$6:$N$179),"0%"))
A5: No. | B5: Chapter | C5: Section | D5: Requirement | E5: Check Points | F5: Legal Reference | G5: ISO/IEC 27001:2022 Ref. | H5: Core | I5: Scope | J5: Implemented | K5: Documented | L5: Effectiveness | M5: Evidence / Source | N5: Score | O5: Work Package Required | P5: Gap Description | Q5: Recommended Action / Work Package | R5: Responsible | S5: Target Date | T5: Effort | U5: Finding ID
A6: 1.1.1 | B6: 1 Policy on the security of network and information systems | C6: 1.1 Policy on the security of network and information systems | D6: For the purpose of Article 21(2), point (a) of Directive (EU) 2022/2555, the policy on the security of network and information systems shall: | E6: (a) set out the relevant entities’ approach to managing the security of their network and information systems; (b) be appropriate to and complementary with the relevant entities’ business strategy and objectives; (c) set out network and information security objectives; (d) include a commitment to continual improvement of the security of network and information systems; (e) include a commitment to provide the appropriate resources needed for its implementation, including the necessary staff, financial resources, processes, tools and technologies; (f) be communicated to and acknowledged by relevant employees and relevant interested external parties; (g) lay down roles and responsibilities pursuant to point 1.2; (h) list the documentation to be kept and the duration of retention of the documentation; (i) list the topic-specific policies; (j) lay down indicators and measures to monitor its implementation and the current status of relevant entities’ maturity level of network and information security; (k) indicate the date of the formal approval by the management bodies of the relevant entities (the ‘management bodies’). | F6: § 30 Abs. 2 Nr. 1 BSIG | G6: 5.2, A.5.1, A.5.36, A.5.4, 9.3 | H6: Yes | I6: In Scope | N6: =IF($I6<>"In Scope","",IF(COUNTA($J6:$L6)-COUNTIF($J6:$L6,"N/A")=0,"",(COUNTIF($J6:$L6,"Yes")+COUNTIF($J6:$L6,"Effective")+0.5*COUNTIF($J6:$L6,"Partial")+0.25*COUNTIF($J6:$L6,"Not Tested"))/(COUNTA($J6:$L6)-COUNTIF($J6:$L6,"N/A")))) | O6: =IF(OR($I6<>"In Scope",COUNTA($J6:$L6)=0),"",IF(COUNTIF($J6:$K6,"No")+COUNTIF($J6:$K6,"Partial")+COUNTIF($L6,"Partial")+COUNTIF($L6,"Not Tested")+COUNTIF($L6,"Ineffective")>0,"Yes","No")) | U6: =IF($O6<>"Yes","",Lists!$P$6&"-"&$A6)
A7: 1.1.2 | B7: 1 Policy on the security of network and information systems | C7: 1.1 Policy on the security of network and information systems | D7: The network and information system security policy shall be reviewed and, where appropriate, updated by management bodies at least annually and when significant incidents or significant changes to operations or risks occur. The result of the reviews shall be documented. | F7: § 30 Abs. 2 Nr. 1 BSIG | G7: 5.2, A.5.1, A.5.36, A.5.4, 9.3 | I7: In Scope | N7: =IF($I7<>"In Scope","",IF(COUNTA($J7:$L7)-COUNTIF($J7:$L7,"N/A")=0,"",(COUNTIF($J7:$L7,"Yes")+COUNTIF($J7:$L7,"Effective")+0.5*COUNTIF($J7:$L7,"Partial")+0.25*COUNTIF($J7:$L7,"Not Tested"))/(COUNTA($J7:$L7)-COUNTIF($J7:$L7,"N/A")))) | O7: =IF(OR($I7<>"In Scope",COUNTA($J7:$L7)=0),"",IF(COUNTIF($J7:$K7,"No")+COUNTIF($J7:$K7,"Partial")+COUNTIF($L7,"Partial")+COUNTIF($L7,"Not Tested")+COUNTIF($L7,"Ineffective")>0,"Yes","No")) | U7: =IF($O7<>"Yes","",Lists!$P$6&"-"&$A7)
A8: 1.2.1 | B8: 1 Policy on the security of network and information systems | C8: 1.2 Roles, responsibilities and authorities | D8: As part of their policy on the security of network and information systems referred to in point 1.1, the relevant entities shall lay down responsibilities and authorities for network and information system security and assign them to roles, allocate them according to the relevant entities’ needs, and communicate them to the management bodies. | F8: § 30 Abs. 2 Nr. 1 BSIG | G8: 5.3, A.5.2, A.5.3, A.5.4 | H8: Yes | I8: In Scope | N8: =IF($I8<>"In Scope","",IF(COUNTA($J8:$L8)-COUNTIF($J8:$L8,"N/A")=0,"",(COUNTIF($J8:$L8,"Yes")+COUNTIF($J8:$L8,"Effective")+0.5*COUNTIF($J8:$L8,"Partial")+0.25*COUNTIF($J8:$L8,"Not Tested"))/(COUNTA($J8:$L8)-COUNTIF($J8:$L8,"N/A")))) | O8: =IF(OR($I8<>"In Scope",COUNTA($J8:$L8)=0),"",IF(COUNTIF($J8:$K8,"No")+COUNTIF($J8:$K8,"Partial")+COUNTIF($L8,"Partial")+COUNTIF($L8,"Not Tested")+COUNTIF($L8,"Ineffective")>0,"Yes","No")) | U8: =IF($O8<>"Yes","",Lists!$P$6&"-"&$A8)
A9: 1.2.2 | B9: 1 Policy on the security of network and information systems | C9: 1.2 Roles, responsibilities and authorities | D9: The relevant entities shall require all personnel and third parties to apply network and information system security in accordance with the established network and information security policy, topic-specific policies and procedures of the relevant entities. | F9: § 30 Abs. 2 Nr. 1 BSIG | G9: 5.3, A.5.2, A.5.3, A.5.4 | I9: In Scope | N9: =IF($I9<>"In Scope","",IF(COUNTA($J9:$L9)-COUNTIF($J9:$L9,"N/A")=0,"",(COUNTIF($J9:$L9,"Yes")+COUNTIF($J9:$L9,"Effective")+0.5*COUNTIF($J9:$L9,"Partial")+0.25*COUNTIF($J9:$L9,"Not Tested"))/(COUNTA($J9:$L9)-COUNTIF($J9:$L9,"N/A")))) | O9: =IF(OR($I9<>"In Scope",COUNTA($J9:$L9)=0),"",IF(COUNTIF($J9:$K9,"No")+COUNTIF($J9:$K9,"Partial")+COUNTIF($L9,"Partial")+COUNTIF($L9,"Not Tested")+COUNTIF($L9,"Ineffective")>0,"Yes","No")) | U9: =IF($O9<>"Yes","",Lists!$P$6&"-"&$A9)
A10: 1.2.3 | B10: 1 Policy on the security of network and information systems | C10: 1.2 Roles, responsibilities and authorities | D10: At least one person shall report directly to the management bodies on matters of network and information system security. | F10: § 30 Abs. 2 Nr. 1 BSIG | G10: 5.3, A.5.2, A.5.3, A.5.4 | I10: In Scope | N10: =IF($I10<>"In Scope","",IF(COUNTA($J10:$L10)-COUNTIF($J10:$L10,"N/A")=0,"",(COUNTIF($J10:$L10,"Yes")+COUNTIF($J10:$L10,"Effective")+0.5*COUNTIF($J10:$L10,"Partial")+0.25*COUNTIF($J10:$L10,"Not Tested"))/(COUNTA($J10:$L10)-COUNTIF($J10:$L10,"N/A")))) | O10: =IF(OR($I10<>"In Scope",COUNTA($J10:$L10)=0),"",IF(COUNTIF($J10:$K10,"No")+COUNTIF($J10:$K10,"Partial")+COUNTIF($L10,"Partial")+COUNTIF($L10,"Not Tested")+COUNTIF($L10,"Ineffective")>0,"Yes","No")) | U10: =IF($O10<>"Yes","",Lists!$P$6&"-"&$A10)
A11: 1.2.4 | B11: 1 Policy on the security of network and information systems | C11: 1.2 Roles, responsibilities and authorities | D11: Depending on the size of the relevant entities, network and information system security shall be covered by dedicated roles or duties carried out in addition to existing roles. | F11: § 30 Abs. 2 Nr. 1 BSIG | G11: 5.3, A.5.2, A.5.3, A.5.4 | I11: In Scope | N11: =IF($I11<>"In Scope","",IF(COUNTA($J11:$L11)-COUNTIF($J11:$L11,"N/A")=0,"",(COUNTIF($J11:$L11,"Yes")+COUNTIF($J11:$L11,"Effective")+0.5*COUNTIF($J11:$L11,"Partial")+0.25*COUNTIF($J11:$L11,"Not Tested"))/(COUNTA($J11:$L11)-COUNTIF($J11:$L11,"N/A")))) | O11: =IF(OR($I11<>"In Scope",COUNTA($J11:$L11)=0),"",IF(COUNTIF($J11:$K11,"No")+COUNTIF($J11:$K11,"Partial")+COUNTIF($L11,"Partial")+COUNTIF($L11,"Not Tested")+COUNTIF($L11,"Ineffective")>0,"Yes","No")) | U11: =IF($O11<>"Yes","",Lists!$P$6&"-"&$A11)
A12: 1.2.5 | B12: 1 Policy on the security of network and information systems | C12: 1.2 Roles, responsibilities and authorities | D12: Conflicting duties and conflicting areas of responsibility shall be segregated, where applicable. | F12: § 30 Abs. 2 Nr. 1 BSIG | G12: 5.3, A.5.2, A.5.3, A.5.4 | I12: In Scope | N12: =IF($I12<>"In Scope","",IF(COUNTA($J12:$L12)-COUNTIF($J12:$L12,"N/A")=0,"",(COUNTIF($J12:$L12,"Yes")+COUNTIF($J12:$L12,"Effective")+0.5*COUNTIF($J12:$L12,"Partial")+0.25*COUNTIF($J12:$L12,"Not Tested"))/(COUNTA($J12:$L12)-COUNTIF($J12:$L12,"N/A")))) | O12: =IF(OR($I12<>"In Scope",COUNTA($J12:$L12)=0),"",IF(COUNTIF($J12:$K12,"No")+COUNTIF($J12:$K12,"Partial")+COUNTIF($L12,"Partial")+COUNTIF($L12,"Not Tested")+COUNTIF($L12,"Ineffective")>0,"Yes","No")) | U12: =IF($O12<>"Yes","",Lists!$P$6&"-"&$A12)
A13: 1.2.6 | B13: 1 Policy on the security of network and information systems | C13: 1.2 Roles, responsibilities and authorities | D13: shall be reviewed and, where appropriate, updated by management bodies at planned intervals and when significant incidents or significant changes to operations or risks occur. | F13: § 30 Abs. 2 Nr. 1 BSIG | G13: 5.3, A.5.2, A.5.3, A.5.4 | I13: In Scope | N13: =IF($I13<>"In Scope","",IF(COUNTA($J13:$L13)-COUNTIF($J13:$L13,"N/A")=0,"",(COUNTIF($J13:$L13,"Yes")+COUNTIF($J13:$L13,"Effective")+0.5*COUNTIF($J13:$L13,"Partial")+0.25*COUNTIF($J13:$L13,"Not Tested"))/(COUNTA($J13:$L13)-COUNTIF($J13:$L13,"N/A")))) | O13: =IF(OR($I13<>"In Scope",COUNTA($J13:$L13)=0),"",IF(COUNTIF($J13:$K13,"No")+COUNTIF($J13:$K13,"Partial")+COUNTIF($L13,"Partial")+COUNTIF($L13,"Not Tested")+COUNTIF($L13,"Ineffective")>0,"Yes","No")) | U13: =IF($O13<>"Yes","",Lists!$P$6&"-"&$A13)
A14: 2.1.1 | B14: 2 Risk management policy | C14: 2.1 Risk management framework | D14: For the purpose of Article 21(2), point (a) of Directive (EU) 2022/2555, the relevant entities shall establish and maintain an appropriate risk management framework to identify and address the risks posed to the security of network and information systems. The relevant entities shall perform and document risk assessments and, based on the results, establish, implement and monitor a risk treatment plan. Risk assessment results and residual risks shall be accepted by management bodies or, where applicable, by persons who are accountable and have the authority to manage risks, provided that the relevant entities ensure adequate reporting to the management bodies. | F14: § 30 Abs. 2 Nr. 1 BSIG | G14: 6.1, 6.1.2, 6.1.3, 6.2, 8.2, 8.3, A.5.7, A.5.19, A.5.20, A.5.21 | H14: Yes | I14: In Scope | N14: =IF($I14<>"In Scope","",IF(COUNTA($J14:$L14)-COUNTIF($J14:$L14,"N/A")=0,"",(COUNTIF($J14:$L14,"Yes")+COUNTIF($J14:$L14,"Effective")+0.5*COUNTIF($J14:$L14,"Partial")+0.25*COUNTIF($J14:$L14,"Not Tested"))/(COUNTA($J14:$L14)-COUNTIF($J14:$L14,"N/A")))) | O14: =IF(OR($I14<>"In Scope",COUNTA($J14:$L14)=0),"",IF(COUNTIF($J14:$K14,"No")+COUNTIF($J14:$K14,"Partial")+COUNTIF($L14,"Partial")+COUNTIF($L14,"Not Tested")+COUNTIF($L14,"Ineffective")>0,"Yes","No")) | U14: =IF($O14<>"Yes","",Lists!$P$6&"-"&$A14)
A15: 2.1.2 | B15: 2 Risk management policy | C15: 2.1 Risk management framework | D15: For the purpose of point 2.1.1, the relevant entities shall establish procedures for identification, analysis, assessment and treatment of risks (‘cybersecurity risk management process’). The cybersecurity risk management process shall be an integral part of the relevant entities’ overall risk management process, where applicable. As part of the cybersecurity risk management process, the relevant entities shall: | E15: (a) follow a risk management methodology; (b) establish the risk tolerance level in accordance with the risk appetite of the relevant entities; (c) establish and maintain relevant risk criteria; (d) in line with an all-hazards approach, identify and document the risks posed to the security of network and information systems, in particular in relation to third parties and risks that could lead to disruptions in the availability, integrity, authenticity and confidentiality of the network and information systems, including the identification of single point of failures; (e) analyse the risks posed to the security of network and information systems, including threat, likelihood, impact, and risk level, taking into account cyber threat intelligence and vulnerabilities; (f) evaluate the identified risks based on the risk criteria; (g) identify and prioritise appropriate risk treatment options and measures; (h) continuously monitor the implementation of the risk treatment measures; (i) identify who is responsible for implementing the risk treatment measures and when they should be implemented; (j) document the chosen risk treatment measures in a risk treatment plan and the reasons justifying the acceptance of residual risks in a comprehensible manner. | F15: § 30 Abs. 2 Nr. 1 BSIG | G15: 6.1, 6.1.2, 6.1.3, 6.2, 8.2, 8.3, A.5.7, A.5.19, A.5.20, A.5.21 | I15: In Scope | N15: =IF($I15<>"In Scope","",IF(COUNTA($J15:$L15)-COUNTIF($J15:$L15,"N/A")=0,"",(COUNTIF($J15:$L15,"Yes")+COUNTIF($J15:$L15,"Effective")+0.5*COUNTIF($J15:$L15,"Partial")+0.25*COUNTIF($J15:$L15,"Not Tested"))/(COUNTA($J15:$L15)-COUNTIF($J15:$L15,"N/A")))) | O15: =IF(OR($I15<>"In Scope",COUNTA($J15:$L15)=0),"",IF(COUNTIF($J15:$K15,"No")+COUNTIF($J15:$K15,"Partial")+COUNTIF($L15,"Partial")+COUNTIF($L15,"Not Tested")+COUNTIF($L15,"Ineffective")>0,"Yes","No")) | U15: =IF($O15<>"Yes","",Lists!$P$6&"-"&$A15)
A16: 2.1.3 | B16: 2 Risk management policy | C16: 2.1 Risk management framework | D16: When identifying and prioritising appropriate risk treatment options and measures, the relevant entities shall take into account the risk assessment results, the results of the procedure to assess the effectiveness of cybersecurity risk- management measures, the cost of implementation in relation to the expected benefit, the asset classification referred to in point 12.1, and the business impact analysis referred to in point 4.1.3. | F16: § 30 Abs. 2 Nr. 1 BSIG | G16: 6.1, 6.1.2, 6.1.3, 6.2, 8.2, 8.3, A.5.7, A.5.19, A.5.20, A.5.21 | I16: In Scope | N16: =IF($I16<>"In Scope","",IF(COUNTA($J16:$L16)-COUNTIF($J16:$L16,"N/A")=0,"",(COUNTIF($J16:$L16,"Yes")+COUNTIF($J16:$L16,"Effective")+0.5*COUNTIF($J16:$L16,"Partial")+0.25*COUNTIF($J16:$L16,"Not Tested"))/(COUNTA($J16:$L16)-COUNTIF($J16:$L16,"N/A")))) | O16: =IF(OR($I16<>"In Scope",COUNTA($J16:$L16)=0),"",IF(COUNTIF($J16:$K16,"No")+COUNTIF($J16:$K16,"Partial")+COUNTIF($L16,"Partial")+COUNTIF($L16,"Not Tested")+COUNTIF($L16,"Ineffective")>0,"Yes","No")) | U16: =IF($O16<>"Yes","",Lists!$P$6&"-"&$A16)
A17: 2.1.4 | B17: 2 Risk management policy | C17: 2.1 Risk management framework | D17: The relevant entities shall review and, where appropriate, update the risk assessment results and the risk treatment plan at planned intervals and at least annually, and when significant changes to operations or risks or significant incidents occur. | F17: § 30 Abs. 2 Nr. 1 BSIG | G17: 6.1, 6.1.2, 6.1.3, 6.2, 8.2, 8.3, A.5.7, A.5.19, A.5.20, A.5.21 | I17: In Scope | N17: =IF($I17<>"In Scope","",IF(COUNTA($J17:$L17)-COUNTIF($J17:$L17,"N/A")=0,"",(COUNTIF($J17:$L17,"Yes")+COUNTIF($J17:$L17,"Effective")+0.5*COUNTIF($J17:$L17,"Partial")+0.25*COUNTIF($J17:$L17,"Not Tested"))/(COUNTA($J17:$L17)-COUNTIF($J17:$L17,"N/A")))) | O17: =IF(OR($I17<>"In Scope",COUNTA($J17:$L17)=0),"",IF(COUNTIF($J17:$K17,"No")+COUNTIF($J17:$K17,"Partial")+COUNTIF($L17,"Partial")+COUNTIF($L17,"Not Tested")+COUNTIF($L17,"Ineffective")>0,"Yes","No")) | U17: =IF($O17<>"Yes","",Lists!$P$6&"-"&$A17)
A18: 2.2.1 | B18: 2 Risk management policy | C18: 2.2 Compliance monitoring | D18: The relevant entities shall regularly review the compliance with their policies on network and information system security, topic-specific policies, rules, and standards. The management bodies shall be informed of the status of network and information security on the basis of the compliance reviews by means of regular reporting. | F18: § 30 Abs. 2 Nr. 1 BSIG | G18: 9.2, A.5.31, A.5.35, A.5.36 | H18: Yes | I18: In Scope | N18: =IF($I18<>"In Scope","",IF(COUNTA($J18:$L18)-COUNTIF($J18:$L18,"N/A")=0,"",(COUNTIF($J18:$L18,"Yes")+COUNTIF($J18:$L18,"Effective")+0.5*COUNTIF($J18:$L18,"Partial")+0.25*COUNTIF($J18:$L18,"Not Tested"))/(COUNTA($J18:$L18)-COUNTIF($J18:$L18,"N/A")))) | O18: =IF(OR($I18<>"In Scope",COUNTA($J18:$L18)=0),"",IF(COUNTIF($J18:$K18,"No")+COUNTIF($J18:$K18,"Partial")+COUNTIF($L18,"Partial")+COUNTIF($L18,"Not Tested")+COUNTIF($L18,"Ineffective")>0,"Yes","No")) | U18: =IF($O18<>"Yes","",Lists!$P$6&"-"&$A18)
A19: 2.2.2 | B19: 2 Risk management policy | C19: 2.2 Compliance monitoring | D19: The relevant entities shall put in place an effective compliance reporting system which shall be appropriate to their structures, operating environments and threat landscapes. The compliance reporting system shall be capable to provide to the management bodies an informed view of the current state of the relevant entities’ management of risks. | F19: § 30 Abs. 2 Nr. 1 BSIG | G19: 9.2, A.5.31, A.5.35, A.5.36 | I19: In Scope | N19: =IF($I19<>"In Scope","",IF(COUNTA($J19:$L19)-COUNTIF($J19:$L19,"N/A")=0,"",(COUNTIF($J19:$L19,"Yes")+COUNTIF($J19:$L19,"Effective")+0.5*COUNTIF($J19:$L19,"Partial")+0.25*COUNTIF($J19:$L19,"Not Tested"))/(COUNTA($J19:$L19)-COUNTIF($J19:$L19,"N/A")))) | O19: =IF(OR($I19<>"In Scope",COUNTA($J19:$L19)=0),"",IF(COUNTIF($J19:$K19,"No")+COUNTIF($J19:$K19,"Partial")+COUNTIF($L19,"Partial")+COUNTIF($L19,"Not Tested")+COUNTIF($L19,"Ineffective")>0,"Yes","No")) | U19: =IF($O19<>"Yes","",Lists!$P$6&"-"&$A19)
A20: 2.2.3 | B20: 2 Risk management policy | C20: 2.2 Compliance monitoring | D20: The relevant entities shall perform the compliance monitoring at planned intervals and when significant incidents or significant changes to operations or risks occur. | F20: § 30 Abs. 2 Nr. 1 BSIG | G20: 9.2, A.5.31, A.5.35, A.5.36 | I20: In Scope | N20: =IF($I20<>"In Scope","",IF(COUNTA($J20:$L20)-COUNTIF($J20:$L20,"N/A")=0,"",(COUNTIF($J20:$L20,"Yes")+COUNTIF($J20:$L20,"Effective")+0.5*COUNTIF($J20:$L20,"Partial")+0.25*COUNTIF($J20:$L20,"Not Tested"))/(COUNTA($J20:$L20)-COUNTIF($J20:$L20,"N/A")))) | O20: =IF(OR($I20<>"In Scope",COUNTA($J20:$L20)=0),"",IF(COUNTIF($J20:$K20,"No")+COUNTIF($J20:$K20,"Partial")+COUNTIF($L20,"Partial")+COUNTIF($L20,"Not Tested")+COUNTIF($L20,"Ineffective")>0,"Yes","No")) | U20: =IF($O20<>"Yes","",Lists!$P$6&"-"&$A20)
A21: 2.3.1 | B21: 2 Risk management policy | C21: 2.3 Independent review of information and network security | D21: The relevant entities shall review independently their approach to managing network and information system security and its implementation including people, processes and technologies. | F21: § 30 Abs. 2 Nr. 1 BSIG | G21: 9.2, 10.1, A.5.35, A.8.34 | H21: Yes | I21: In Scope | N21: =IF($I21<>"In Scope","",IF(COUNTA($J21:$L21)-COUNTIF($J21:$L21,"N/A")=0,"",(COUNTIF($J21:$L21,"Yes")+COUNTIF($J21:$L21,"Effective")+0.5*COUNTIF($J21:$L21,"Partial")+0.25*COUNTIF($J21:$L21,"Not Tested"))/(COUNTA($J21:$L21)-COUNTIF($J21:$L21,"N/A")))) | O21: =IF(OR($I21<>"In Scope",COUNTA($J21:$L21)=0),"",IF(COUNTIF($J21:$K21,"No")+COUNTIF($J21:$K21,"Partial")+COUNTIF($L21,"Partial")+COUNTIF($L21,"Not Tested")+COUNTIF($L21,"Ineffective")>0,"Yes","No")) | U21: =IF($O21<>"Yes","",Lists!$P$6&"-"&$A21)
A22: 2.3.2 | B22: 2 Risk management policy | C22: 2.3 Independent review of information and network security | D22: The relevant entities shall develop and maintain processes to conduct independent reviews which shall be carried out by individuals with appropriate audit competence. Where the independent review is conducted by staff members of the relevant entity, the persons conducting the reviews shall not be in the line of authority of the personnel of the area under review. If the size of the relevant entities does not allow such separation of line of authority, the relevant entities shall put in place alternative measures to guarantee the impartiality of the reviews. | F22: § 30 Abs. 2 Nr. 1 BSIG | G22: 9.2, 10.1, A.5.35, A.8.34 | I22: In Scope | N22: =IF($I22<>"In Scope","",IF(COUNTA($J22:$L22)-COUNTIF($J22:$L22,"N/A")=0,"",(COUNTIF($J22:$L22,"Yes")+COUNTIF($J22:$L22,"Effective")+0.5*COUNTIF($J22:$L22,"Partial")+0.25*COUNTIF($J22:$L22,"Not Tested"))/(COUNTA($J22:$L22)-COUNTIF($J22:$L22,"N/A")))) | O22: =IF(OR($I22<>"In Scope",COUNTA($J22:$L22)=0),"",IF(COUNTIF($J22:$K22,"No")+COUNTIF($J22:$K22,"Partial")+COUNTIF($L22,"Partial")+COUNTIF($L22,"Not Tested")+COUNTIF($L22,"Ineffective")>0,"Yes","No")) | U22: =IF($O22<>"Yes","",Lists!$P$6&"-"&$A22)
A23: 2.3.3 | B23: 2 Risk management policy | C23: 2.3 Independent review of information and network security | D23: The results of the independent reviews, including the results from the compliance monitoring pursuant to point 2.2 and the monitoring and measurement pursuant to point 7, shall be reported to the management bodies. Corrective actions shall be taken or residual risk accepted according to the relevant entities’ risk acceptance criteria. | F23: § 30 Abs. 2 Nr. 1 BSIG | G23: 9.2, 10.1, A.5.35, A.8.34 | I23: In Scope | N23: =IF($I23<>"In Scope","",IF(COUNTA($J23:$L23)-COUNTIF($J23:$L23,"N/A")=0,"",(COUNTIF($J23:$L23,"Yes")+COUNTIF($J23:$L23,"Effective")+0.5*COUNTIF($J23:$L23,"Partial")+0.25*COUNTIF($J23:$L23,"Not Tested"))/(COUNTA($J23:$L23)-COUNTIF($J23:$L23,"N/A")))) | O23: =IF(OR($I23<>"In Scope",COUNTA($J23:$L23)=0),"",IF(COUNTIF($J23:$K23,"No")+COUNTIF($J23:$K23,"Partial")+COUNTIF($L23,"Partial")+COUNTIF($L23,"Not Tested")+COUNTIF($L23,"Ineffective")>0,"Yes","No")) | U23: =IF($O23<>"Yes","",Lists!$P$6&"-"&$A23)
A24: 2.3.4 | B24: 2 Risk management policy | C24: 2.3 Independent review of information and network security | D24: The independent reviews shall take place at planned intervals and when significant incidents or significant changes to operations or risks occur. | F24: § 30 Abs. 2 Nr. 1 BSIG | G24: 9.2, 10.1, A.5.35, A.8.34 | I24: In Scope | N24: =IF($I24<>"In Scope","",IF(COUNTA($J24:$L24)-COUNTIF($J24:$L24,"N/A")=0,"",(COUNTIF($J24:$L24,"Yes")+COUNTIF($J24:$L24,"Effective")+0.5*COUNTIF($J24:$L24,"Partial")+0.25*COUNTIF($J24:$L24,"Not Tested"))/(COUNTA($J24:$L24)-COUNTIF($J24:$L24,"N/A")))) | O24: =IF(OR($I24<>"In Scope",COUNTA($J24:$L24)=0),"",IF(COUNTIF($J24:$K24,"No")+COUNTIF($J24:$K24,"Partial")+COUNTIF($L24,"Partial")+COUNTIF($L24,"Not Tested")+COUNTIF($L24,"Ineffective")>0,"Yes","No")) | U24: =IF($O24<>"Yes","",Lists!$P$6&"-"&$A24)
A25: 3.1.1 | B25: 3 Incident handling | C25: 3.1 Incident handling policy | D25: For the purpose of Article 21(2), point (b) of Directive (EU) 2022/2555, the relevant entities shall establish and implement an incident handling policy laying down the roles, responsibilities, and procedures for detecting, analysing, containing or responding to, recovering from, documenting and reporting of incidents in a timely manner. | F25: § 30 Abs. 2 Nr. 2 BSIG | G25: A.5 .24 | H25: Yes | I25: In Scope | N25: =IF($I25<>"In Scope","",IF(COUNTA($J25:$L25)-COUNTIF($J25:$L25,"N/A")=0,"",(COUNTIF($J25:$L25,"Yes")+COUNTIF($J25:$L25,"Effective")+0.5*COUNTIF($J25:$L25,"Partial")+0.25*COUNTIF($J25:$L25,"Not Tested"))/(COUNTA($J25:$L25)-COUNTIF($J25:$L25,"N/A")))) | O25: =IF(OR($I25<>"In Scope",COUNTA($J25:$L25)=0),"",IF(COUNTIF($J25:$K25,"No")+COUNTIF($J25:$K25,"Partial")+COUNTIF($L25,"Partial")+COUNTIF($L25,"Not Tested")+COUNTIF($L25,"Ineffective")>0,"Yes","No")) | U25: =IF($O25<>"Yes","",Lists!$P$6&"-"&$A25)
A26: 3.1.2 | B26: 3 Incident handling | C26: 3.1 Incident handling policy | D26: The policy referred to in point 3.1.1 shall be coherent with the business continuity and disaster recovery plan referred to in point 4.1. The policy shall include: | E26: (a) a categorisation system for incidents that is consistent with the event assessment and classification carried out pursuant to point 3.4.1; (b) effective communication plans including for escalation and reporting; (c) assignment of roles to detect and appropriately respond to incidents to competent employees; (d) documents to be used in the course of incident detection and response such as incident response manuals, escalation charts, contact lists and templates. | F26: § 30 Abs. 2 Nr. 2 BSIG | G26: A.5 .24 | I26: In Scope | N26: =IF($I26<>"In Scope","",IF(COUNTA($J26:$L26)-COUNTIF($J26:$L26,"N/A")=0,"",(COUNTIF($J26:$L26,"Yes")+COUNTIF($J26:$L26,"Effective")+0.5*COUNTIF($J26:$L26,"Partial")+0.25*COUNTIF($J26:$L26,"Not Tested"))/(COUNTA($J26:$L26)-COUNTIF($J26:$L26,"N/A")))) | O26: =IF(OR($I26<>"In Scope",COUNTA($J26:$L26)=0),"",IF(COUNTIF($J26:$K26,"No")+COUNTIF($J26:$K26,"Partial")+COUNTIF($L26,"Partial")+COUNTIF($L26,"Not Tested")+COUNTIF($L26,"Ineffective")>0,"Yes","No")) | U26: =IF($O26<>"Yes","",Lists!$P$6&"-"&$A26)
A27: 3.1.3 | B27: 3 Incident handling | C27: 3.1 Incident handling policy | D27: The roles, responsibilities and procedures laid down in the policy shall be tested and reviewed and, where appropriate, updated at planned intervals and after significant incidents or significant changes to operations or risks. | F27: § 30 Abs. 2 Nr. 2 BSIG | G27: A.5 .24 | I27: In Scope | N27: =IF($I27<>"In Scope","",IF(COUNTA($J27:$L27)-COUNTIF($J27:$L27,"N/A")=0,"",(COUNTIF($J27:$L27,"Yes")+COUNTIF($J27:$L27,"Effective")+0.5*COUNTIF($J27:$L27,"Partial")+0.25*COUNTIF($J27:$L27,"Not Tested"))/(COUNTA($J27:$L27)-COUNTIF($J27:$L27,"N/A")))) | O27: =IF(OR($I27<>"In Scope",COUNTA($J27:$L27)=0),"",IF(COUNTIF($J27:$K27,"No")+COUNTIF($J27:$K27,"Partial")+COUNTIF($L27,"Partial")+COUNTIF($L27,"Not Tested")+COUNTIF($L27,"Ineffective")>0,"Yes","No")) | U27: =IF($O27<>"Yes","",Lists!$P$6&"-"&$A27)
A28: 3.2.1 | B28: 3 Incident handling | C28: 3.2 Monitoring and logging | D28: The relevant entities shall lay down procedures and use tools to monitor and log activities on their network and information systems to detect events that could be considered as incidents and respond accordingly to mitigate the impact. | F28: § 30 Abs. 2 Nr. 2 BSIG | G28: A.5.28, A.8.15, A.8.16, A.8.17 | H28: Yes | I28: In Scope | N28: =IF($I28<>"In Scope","",IF(COUNTA($J28:$L28)-COUNTIF($J28:$L28,"N/A")=0,"",(COUNTIF($J28:$L28,"Yes")+COUNTIF($J28:$L28,"Effective")+0.5*COUNTIF($J28:$L28,"Partial")+0.25*COUNTIF($J28:$L28,"Not Tested"))/(COUNTA($J28:$L28)-COUNTIF($J28:$L28,"N/A")))) | O28: =IF(OR($I28<>"In Scope",COUNTA($J28:$L28)=0),"",IF(COUNTIF($J28:$K28,"No")+COUNTIF($J28:$K28,"Partial")+COUNTIF($L28,"Partial")+COUNTIF($L28,"Not Tested")+COUNTIF($L28,"Ineffective")>0,"Yes","No")) | U28: =IF($O28<>"Yes","",Lists!$P$6&"-"&$A28)
A29: 3.2.2 | B29: 3 Incident handling | C29: 3.2 Monitoring and logging | D29: To the extent feasible, monitoring shall be automated and carried out either continuously or in periodic intervals, subject to business capabilities. The relevant entities shall implement their monitoring activities in a way which minimises false positives and false negatives. | F29: § 30 Abs. 2 Nr. 2 BSIG | G29: A.5.28, A.8.15, A.8.16, A.8.17 | I29: In Scope | N29: =IF($I29<>"In Scope","",IF(COUNTA($J29:$L29)-COUNTIF($J29:$L29,"N/A")=0,"",(COUNTIF($J29:$L29,"Yes")+COUNTIF($J29:$L29,"Effective")+0.5*COUNTIF($J29:$L29,"Partial")+0.25*COUNTIF($J29:$L29,"Not Tested"))/(COUNTA($J29:$L29)-COUNTIF($J29:$L29,"N/A")))) | O29: =IF(OR($I29<>"In Scope",COUNTA($J29:$L29)=0),"",IF(COUNTIF($J29:$K29,"No")+COUNTIF($J29:$K29,"Partial")+COUNTIF($L29,"Partial")+COUNTIF($L29,"Not Tested")+COUNTIF($L29,"Ineffective")>0,"Yes","No")) | U29: =IF($O29<>"Yes","",Lists!$P$6&"-"&$A29)
A30: 3.2.3 | B30: 3 Incident handling | C30: 3.2 Monitoring and logging | D30: Based on the procedures referred to in point 3.2.1, the relevant entities shall maintain, document, and review logs. The relevant entities shall establish a list of assets to be subject to logging based on the results of the risk assessment carried out pursuant to point 2.1. Where appropriate, logs shall include: | E30: (a) relevant outbound and inbound network traffic; (b) creation, modification or deletion of users of the relevant entities’ network and information systems and extension of the permissions; (c) access to systems and applications; (d) authentication-related events; (e) all privileged access to systems and applications, and activities performed by administrative accounts; (f) access or changes to critical configuration and backup files; (g) event logs and logs from security tools, such as antivirus, intrusion detection systems or firewalls; (h) use of system resources, as well as their performance; (i) physical access to facilities; (j) access to and use of their network equipment and devices; (k) activation, stopping and pausing of the various logs; (l) environmental events. | F30: § 30 Abs. 2 Nr. 2 BSIG | G30: A.5.28, A.8.15, A.8.16, A.8.17 | I30: In Scope | N30: =IF($I30<>"In Scope","",IF(COUNTA($J30:$L30)-COUNTIF($J30:$L30,"N/A")=0,"",(COUNTIF($J30:$L30,"Yes")+COUNTIF($J30:$L30,"Effective")+0.5*COUNTIF($J30:$L30,"Partial")+0.25*COUNTIF($J30:$L30,"Not Tested"))/(COUNTA($J30:$L30)-COUNTIF($J30:$L30,"N/A")))) | O30: =IF(OR($I30<>"In Scope",COUNTA($J30:$L30)=0),"",IF(COUNTIF($J30:$K30,"No")+COUNTIF($J30:$K30,"Partial")+COUNTIF($L30,"Partial")+COUNTIF($L30,"Not Tested")+COUNTIF($L30,"Ineffective")>0,"Yes","No")) | U30: =IF($O30<>"Yes","",Lists!$P$6&"-"&$A30)
A31: 3.2.4 | B31: 3 Incident handling | C31: 3.2 Monitoring and logging | D31: The logs shall be regularly reviewed for any unusual or unwanted trends. Where appropriate, the relevant entities shall lay down appropriate values for alarm thresholds. If the laid down values for alarm threshold are exceeded, an alarm shall be triggered, where appropriate, automatically. The relevant entities shall ensure that, in case of an alarm, a qualified and appropriate response is initiated in a timely manner. | F31: § 30 Abs. 2 Nr. 2 BSIG | G31: A.5.28, A.8.15, A.8.16, A.8.17 | I31: In Scope | N31: =IF($I31<>"In Scope","",IF(COUNTA($J31:$L31)-COUNTIF($J31:$L31,"N/A")=0,"",(COUNTIF($J31:$L31,"Yes")+COUNTIF($J31:$L31,"Effective")+0.5*COUNTIF($J31:$L31,"Partial")+0.25*COUNTIF($J31:$L31,"Not Tested"))/(COUNTA($J31:$L31)-COUNTIF($J31:$L31,"N/A")))) | O31: =IF(OR($I31<>"In Scope",COUNTA($J31:$L31)=0),"",IF(COUNTIF($J31:$K31,"No")+COUNTIF($J31:$K31,"Partial")+COUNTIF($L31,"Partial")+COUNTIF($L31,"Not Tested")+COUNTIF($L31,"Ineffective")>0,"Yes","No")) | U31: =IF($O31<>"Yes","",Lists!$P$6&"-"&$A31)
A32: 3.2.5 | B32: 3 Incident handling | C32: 3.2 Monitoring and logging | D32: The relevant entities shall maintain and back up logs for a predefined period and shall protect them from unauthorised access or changes. | F32: § 30 Abs. 2 Nr. 2 BSIG | G32: A.5.28, A.8.15, A.8.16, A.8.17 | I32: In Scope | N32: =IF($I32<>"In Scope","",IF(COUNTA($J32:$L32)-COUNTIF($J32:$L32,"N/A")=0,"",(COUNTIF($J32:$L32,"Yes")+COUNTIF($J32:$L32,"Effective")+0.5*COUNTIF($J32:$L32,"Partial")+0.25*COUNTIF($J32:$L32,"Not Tested"))/(COUNTA($J32:$L32)-COUNTIF($J32:$L32,"N/A")))) | O32: =IF(OR($I32<>"In Scope",COUNTA($J32:$L32)=0),"",IF(COUNTIF($J32:$K32,"No")+COUNTIF($J32:$K32,"Partial")+COUNTIF($L32,"Partial")+COUNTIF($L32,"Not Tested")+COUNTIF($L32,"Ineffective")>0,"Yes","No")) | U32: =IF($O32<>"Yes","",Lists!$P$6&"-"&$A32)
A33: 3.2.6 | B33: 3 Incident handling | C33: 3.2 Monitoring and logging | D33: To the extent feasible, the relevant entities shall ensure that all systems have synchronised time sources to be able to correlate logs between systems for event assessment. The relevant entities shall establish and keep a list of all assets that are being logged and ensure that monitoring and logging systems are redundant. The availability of the monitoring and logging systems shall be monitored independent of the systems they are monitoring. | F33: § 30 Abs. 2 Nr. 2 BSIG | G33: A.5.28, A.8.15, A.8.16, A.8.17 | I33: In Scope | N33: =IF($I33<>"In Scope","",IF(COUNTA($J33:$L33)-COUNTIF($J33:$L33,"N/A")=0,"",(COUNTIF($J33:$L33,"Yes")+COUNTIF($J33:$L33,"Effective")+0.5*COUNTIF($J33:$L33,"Partial")+0.25*COUNTIF($J33:$L33,"Not Tested"))/(COUNTA($J33:$L33)-COUNTIF($J33:$L33,"N/A")))) | O33: =IF(OR($I33<>"In Scope",COUNTA($J33:$L33)=0),"",IF(COUNTIF($J33:$K33,"No")+COUNTIF($J33:$K33,"Partial")+COUNTIF($L33,"Partial")+COUNTIF($L33,"Not Tested")+COUNTIF($L33,"Ineffective")>0,"Yes","No")) | U33: =IF($O33<>"Yes","",Lists!$P$6&"-"&$A33)
A34: 3.2.7 | B34: 3 Incident handling | C34: 3.2 Monitoring and logging | D34: The procedures as well as the list of assets that are being logged shall be reviewed and, where appropriate, updated at regular intervals and after significant incidents. | F34: § 30 Abs. 2 Nr. 2 BSIG | G34: A.5.28, A.8.15, A.8.16, A.8.17 | I34: In Scope | N34: =IF($I34<>"In Scope","",IF(COUNTA($J34:$L34)-COUNTIF($J34:$L34,"N/A")=0,"",(COUNTIF($J34:$L34,"Yes")+COUNTIF($J34:$L34,"Effective")+0.5*COUNTIF($J34:$L34,"Partial")+0.25*COUNTIF($J34:$L34,"Not Tested"))/(COUNTA($J34:$L34)-COUNTIF($J34:$L34,"N/A")))) | O34: =IF(OR($I34<>"In Scope",COUNTA($J34:$L34)=0),"",IF(COUNTIF($J34:$K34,"No")+COUNTIF($J34:$K34,"Partial")+COUNTIF($L34,"Partial")+COUNTIF($L34,"Not Tested")+COUNTIF($L34,"Ineffective")>0,"Yes","No")) | U34: =IF($O34<>"Yes","",Lists!$P$6&"-"&$A34)
A35: 3.3.1 | B35: 3 Incident handling | C35: 3.3 Event reporting | D35: The relevant entities shall put in place a simple mechanism allowing their employees, suppliers, and customers to report suspicious events. | F35: § 30 Abs. 2 Nr. 2 BSIG | G35: A.6.8 | H35: Yes | I35: In Scope | N35: =IF($I35<>"In Scope","",IF(COUNTA($J35:$L35)-COUNTIF($J35:$L35,"N/A")=0,"",(COUNTIF($J35:$L35,"Yes")+COUNTIF($J35:$L35,"Effective")+0.5*COUNTIF($J35:$L35,"Partial")+0.25*COUNTIF($J35:$L35,"Not Tested"))/(COUNTA($J35:$L35)-COUNTIF($J35:$L35,"N/A")))) | O35: =IF(OR($I35<>"In Scope",COUNTA($J35:$L35)=0),"",IF(COUNTIF($J35:$K35,"No")+COUNTIF($J35:$K35,"Partial")+COUNTIF($L35,"Partial")+COUNTIF($L35,"Not Tested")+COUNTIF($L35,"Ineffective")>0,"Yes","No")) | U35: =IF($O35<>"Yes","",Lists!$P$6&"-"&$A35)
A36: 3.3.2 | B36: 3 Incident handling | C36: 3.3 Event reporting | D36: The relevant entities shall, where appropriate, communicate the event reporting mechanism to their suppliers and customers, and shall regularly train their employees how to use the mechanism. | F36: § 30 Abs. 2 Nr. 2 BSIG | G36: A.6.8 | I36: In Scope | N36: =IF($I36<>"In Scope","",IF(COUNTA($J36:$L36)-COUNTIF($J36:$L36,"N/A")=0,"",(COUNTIF($J36:$L36,"Yes")+COUNTIF($J36:$L36,"Effective")+0.5*COUNTIF($J36:$L36,"Partial")+0.25*COUNTIF($J36:$L36,"Not Tested"))/(COUNTA($J36:$L36)-COUNTIF($J36:$L36,"N/A")))) | O36: =IF(OR($I36<>"In Scope",COUNTA($J36:$L36)=0),"",IF(COUNTIF($J36:$K36,"No")+COUNTIF($J36:$K36,"Partial")+COUNTIF($L36,"Partial")+COUNTIF($L36,"Not Tested")+COUNTIF($L36,"Ineffective")>0,"Yes","No")) | U36: =IF($O36<>"Yes","",Lists!$P$6&"-"&$A36)
A37: 3.4.1 | B37: 3 Incident handling | C37: 3.4 Event assessment and classification | D37: The relevant entities shall assess suspicious events to determine whether they constitute incidents and, if so, determine their nature and severity. | F37: § 30 Abs. 2 Nr. 2 BSIG | G37: A.5.25 | H37: Yes | I37: In Scope | N37: =IF($I37<>"In Scope","",IF(COUNTA($J37:$L37)-COUNTIF($J37:$L37,"N/A")=0,"",(COUNTIF($J37:$L37,"Yes")+COUNTIF($J37:$L37,"Effective")+0.5*COUNTIF($J37:$L37,"Partial")+0.25*COUNTIF($J37:$L37,"Not Tested"))/(COUNTA($J37:$L37)-COUNTIF($J37:$L37,"N/A")))) | O37: =IF(OR($I37<>"In Scope",COUNTA($J37:$L37)=0),"",IF(COUNTIF($J37:$K37,"No")+COUNTIF($J37:$K37,"Partial")+COUNTIF($L37,"Partial")+COUNTIF($L37,"Not Tested")+COUNTIF($L37,"Ineffective")>0,"Yes","No")) | U37: =IF($O37<>"Yes","",Lists!$P$6&"-"&$A37)
A38: 3.4.2 | B38: 3 Incident handling | C38: 3.4 Event assessment and classification | D38: For the purpose of point 3.4.1, the relevant entities shall act in the following manner: | E38: (a) carry out the assessment based on predefined criteria laid down in advance, and on a triage to determine prioritisation of incident containment and eradication; (b) assess the existence of recurring incidents as referred to in Article 4 of this Regulation on a quarterly basis; (c) review the appropriate logs for the purposes of event assessment and classification; (d) put in place a process for log correlation and analysis, and (e) reassess and reclassify events in case of new information becoming available or after analysis of previously available information. | F38: § 30 Abs. 2 Nr. 2 BSIG | G38: A.5.25 | I38: In Scope | N38: =IF($I38<>"In Scope","",IF(COUNTA($J38:$L38)-COUNTIF($J38:$L38,"N/A")=0,"",(COUNTIF($J38:$L38,"Yes")+COUNTIF($J38:$L38,"Effective")+0.5*COUNTIF($J38:$L38,"Partial")+0.25*COUNTIF($J38:$L38,"Not Tested"))/(COUNTA($J38:$L38)-COUNTIF($J38:$L38,"N/A")))) | O38: =IF(OR($I38<>"In Scope",COUNTA($J38:$L38)=0),"",IF(COUNTIF($J38:$K38,"No")+COUNTIF($J38:$K38,"Partial")+COUNTIF($L38,"Partial")+COUNTIF($L38,"Not Tested")+COUNTIF($L38,"Ineffective")>0,"Yes","No")) | U38: =IF($O38<>"Yes","",Lists!$P$6&"-"&$A38)
A39: 3.5.1 | B39: 3 Incident handling | C39: 3.5 Incident response | D39: The relevant entities shall respond to incidents in accordance with documented procedures and in a timely manner. | F39: § 30 Abs. 2 Nr. 2 BSIG | G39: A.5.26 | H39: Yes | I39: In Scope | N39: =IF($I39<>"In Scope","",IF(COUNTA($J39:$L39)-COUNTIF($J39:$L39,"N/A")=0,"",(COUNTIF($J39:$L39,"Yes")+COUNTIF($J39:$L39,"Effective")+0.5*COUNTIF($J39:$L39,"Partial")+0.25*COUNTIF($J39:$L39,"Not Tested"))/(COUNTA($J39:$L39)-COUNTIF($J39:$L39,"N/A")))) | O39: =IF(OR($I39<>"In Scope",COUNTA($J39:$L39)=0),"",IF(COUNTIF($J39:$K39,"No")+COUNTIF($J39:$K39,"Partial")+COUNTIF($L39,"Partial")+COUNTIF($L39,"Not Tested")+COUNTIF($L39,"Ineffective")>0,"Yes","No")) | U39: =IF($O39<>"Yes","",Lists!$P$6&"-"&$A39)
A40: 3.5.2 | B40: 3 Incident handling | C40: 3.5 Incident response | D40: The incident response procedures shall include the following stages: | E40: (a) incident containment, to prevent the consequences of the incident from spreading; (b) eradication, to prevent the incident from continuing or reappearing, (c) recovery from the incident, where necessary. | F40: § 30 Abs. 2 Nr. 2 BSIG | G40: A.5.26 | I40: In Scope | N40: =IF($I40<>"In Scope","",IF(COUNTA($J40:$L40)-COUNTIF($J40:$L40,"N/A")=0,"",(COUNTIF($J40:$L40,"Yes")+COUNTIF($J40:$L40,"Effective")+0.5*COUNTIF($J40:$L40,"Partial")+0.25*COUNTIF($J40:$L40,"Not Tested"))/(COUNTA($J40:$L40)-COUNTIF($J40:$L40,"N/A")))) | O40: =IF(OR($I40<>"In Scope",COUNTA($J40:$L40)=0),"",IF(COUNTIF($J40:$K40,"No")+COUNTIF($J40:$K40,"Partial")+COUNTIF($L40,"Partial")+COUNTIF($L40,"Not Tested")+COUNTIF($L40,"Ineffective")>0,"Yes","No")) | U40: =IF($O40<>"Yes","",Lists!$P$6&"-"&$A40)
