Workbook

Sheet Project Overview
A1: NIS2 Group Implementation Project
A2: Project Overview
A3: Version 1.0 | Status: Draft | Classification: Internal use | Document owner: Information Security Officer
A5: Field | B5: Value
A6: Project Name | B6: NIS2 Group Implementation Project
A7: Planned Start | B7: 46286
A8: Planned Completion | B8: 46721
A9: Project Sponsor | B9: Group Management Board
A10: Project Manager | B10: Information Security Officer
A11: Steering Committee | B11: Management Board; IT Coordinator; Data Protection Officer
A12: Geographic Scope | B12: HQ and all subsidiaries
A13: Regulatory Scope | B13: NIS2 implementation and related national requirements in Germany and the Netherlands
A14: Operational Scope | B14: Governance; risk management; incident handling and reporting; business continuity; supply-chain security; vulnerability management; effectiveness reviews; cyber hygiene and training; cryptography; access control; MFA; secure communications; OT security; compliance evidence
A15: Out of Scope | B15: ISO/IEC 27001 certification and full ISO/IEC 27001 implementation beyond what is required for NIS2
A16: Delivery Model | B16: Part-time project alongside normal operations
A17: Assessment Model | B17: Remote assessments; one full pass over all 174 requirements per entity; partly sequential and partly parallel
A18: Project Team Meeting | B18: Every two weeks
A19: Steering Committee Reporting | B19: Every six weeks and at management gates
A20: Priority Model | B20: High; Medium; Low
... A25: Success Criterion | B25: All applicable NIS2 requirements are implemented, documented and subject to an initial effectiveness review, or remaining risks are formally accepted by authorised management

Sheet Dashboard
A1: NIS2 Group Implementation Project
A2: Project Dashboard
A3: Fully formula-based. Values update as soon as the Master Plan, Work Packages, Gates or Risk records change. No refresh required.
A5: Reporting date | B5: =TODAY()
A7: Overall Status | D7: Progress by Phase
A8: Indicator | B8: Value | D8: Phase | E8: Activities | F8: Completed | G8: Progress | H8: Overdue
A9: Activities in plan | B9: =COUNTA('Master Plan'!$A$6:$A$40) | D9: 1. Initiation | E9: =COUNTIF('Master Plan'!$B$6:$B$40,$D9) | F9: =COUNTIFS('Master Plan'!$B$6:$B$40,$D9,'Master Plan'!$M$6:$M$40,"Completed") | G9: =IFERROR(AVERAGEIFS('Master Plan'!$O$6:$O$40,'Master Plan'!$B$6:$B$40,$D9),0) | H9: =COUNTIFS('Master Plan'!$B$6:$B$40,$D9,'Master Plan'!$P$6:$P$40,"Red")
A10: Completed | B10: =COUNTIF('Master Plan'!$M$6:$M$40,"Completed") | D10: 2. Assessment Preparation | E10: =COUNTIF('Master Plan'!$B$6:$B$40,$D10) | F10: =COUNTIFS('Master Plan'!$B$6:$B$40,$D10,'Master Plan'!$M$6:$M$40,"Completed") | G10: =IFERROR(AVERAGEIFS('Master Plan'!$O$6:$O$40,'Master Plan'!$B$6:$B$40,$D10),0) | H10: =COUNTIFS('Master Plan'!$B$6:$B$40,$D10,'Master Plan'!$P$6:$P$40,"Red")
A11: In progress | B11: =COUNTIF('Master Plan'!$M$6:$M$40,"In Progress") | D11: 3. GAP Assessments | E11: =COUNTIF('Master Plan'!$B$6:$B$40,$D11) | F11: =COUNTIFS('Master Plan'!$B$6:$B$40,$D11,'Master Plan'!$M$6:$M$40,"Completed") | G11: =IFERROR(AVERAGEIFS('Master Plan'!$O$6:$O$40,'Master Plan'!$B$6:$B$40,$D11),0) | H11: =COUNTIFS('Master Plan'!$B$6:$B$40,$D11,'Master Plan'!$P$6:$P$40,"Red")
A12: Blocked | B12: =COUNTIF('Master Plan'!$M$6:$M$40,"Blocked") | D12: 4. Consolidation | E12: =COUNTIF('Master Plan'!$B$6:$B$40,$D12) | F12: =COUNTIFS('Master Plan'!$B$6:$B$40,$D12,'Master Plan'!$M$6:$M$40,"Completed") | G12: =IFERROR(AVERAGEIFS('Master Plan'!$O$6:$O$40,'Master Plan'!$B$6:$B$40,$D12),0) | H12: =COUNTIFS('Master Plan'!$B$6:$B$40,$D12,'Master Plan'!$P$6:$P$40,"Red")
A13: Overall progress | B13: =IFERROR(AVERAGE('Master Plan'!$O$6:$O$40),0) | D13: 5. Remediation | E13: =COUNTIF('Master Plan'!$B$6:$B$40,$D13) | F13: =COUNTIFS('Master Plan'!$B$6:$B$40,$D13,'Master Plan'!$M$6:$M$40,"Completed") | G13: =IFERROR(AVERAGEIFS('Master Plan'!$O$6:$O$40,'Master Plan'!$B$6:$B$40,$D13),0) | H13: =COUNTIFS('Master Plan'!$B$6:$B$40,$D13,'Master Plan'!$P$6:$P$40,"Red")
A14: Schedule: Green | B14: =COUNTIF('Master Plan'!$P$6:$P$40,"Green") | D14: 6. Verification | E14: =COUNTIF('Master Plan'!$B$6:$B$40,$D14) | F14: =COUNTIFS('Master Plan'!$B$6:$B$40,$D14,'Master Plan'!$M$6:$M$40,"Completed") | G14: =IFERROR(AVERAGEIFS('Master Plan'!$O$6:$O$40,'Master Plan'!$B$6:$B$40,$D14),0) | H14: =COUNTIFS('Master Plan'!$B$6:$B$40,$D14,'Master Plan'!$P$6:$P$40,"Red")
A15: Schedule: Amber | B15: =COUNTIF('Master Plan'!$P$6:$P$40,"Amber")
A16: Schedule: Red (overdue) | B16: =COUNTIF('Master Plan'!$P$6:$P$40,"Red") | D16: Management Gates
A17: Finishing in next 30 days | B17: =COUNTIFS('Master Plan'!$G$6:$G$40,">="&TODAY(),'Master Plan'!$G$6:$G$40,"<="&TODAY()+30) | D17: Gate | E17: Planned Date | F17: Status | G17: Days to Gate | H17: Open Activities
D18: ='Governance and Gates'!$A$6 | E18: ='Governance and Gates'!$B$6 | F18: ='Governance and Gates'!$G$6 | G18: =IF($E18="","",$E18-TODAY()) | H18: ='Governance and Gates'!$J$6
A19: Work Packages | D19: ='Governance and Gates'!$A$7 | E19: ='Governance and Gates'!$B$7 | F19: ='Governance and Gates'!$G$7 | G19: =IF($E19="","",$E19-TODAY()) | H19: ='Governance and Gates'!$J$7
A20: Indicator | B20: Value | D20: ='Governance and Gates'!$A$8 | E20: ='Governance and Gates'!$B$8 | F20: ='Governance and Gates'!$G$8 | G20: =IF($E20="","",$E20-TODAY()) | H20: ='Governance and Gates'!$J$8
A21: Work packages defined | B21: =COUNTIF('Work Packages'!$E$6:$E$45,"?*") | D21: ='Governance and Gates'!$A$9 | E21: ='Governance and Gates'!$B$9 | F21: ='Governance and Gates'!$G$9 | G21: =IF($E21="","",$E21-TODAY()) | H21: ='Governance and Gates'!$J$9
A22: Not started | B22: =COUNTIFS('Work Packages'!$E$6:$E$45,"?*",'Work Packages'!$N$6:$N$45,"Not Started") | D22: ='Governance and Gates'!$A$10 | E22: ='Governance and Gates'!$B$10 | F22: ='Governance and Gates'!$G$10 | G22: =IF($E22="","",$E22-TODAY()) | H22: ='Governance and Gates'!$J$10
A23: In progress | B23: =COUNTIFS('Work Packages'!$E$6:$E$45,"?*",'Work Packages'!$N$6:$N$45,"In Progress") | D23: ='Governance and Gates'!$A$11 | E23: ='Governance and Gates'!$B$11 | F23: ='Governance and Gates'!$G$11 | G23: =IF($E23="","",$E23-TODAY()) | H23: ='Governance and Gates'!$J$11
A24: Completed | B24: =COUNTIFS('Work Packages'!$E$6:$E$45,"?*",'Work Packages'!$N$6:$N$45,"Completed")
A25: High priority open | B25: =COUNTIFS('Work Packages'!$E$6:$E$45,"?*",'Work Packages'!$G$6:$G$45,"High",'Work Packages'!$N$6:$N$45,"<>Completed") | D25: Legend
A26: Overdue (Red) | B26: =COUNTIF('Work Packages'!$P$6:$P$45,"Red") | D26: Indicator | E26: Meaning
D27: Green | E27: On schedule or completed
A28: Risks, Issues and Decisions | D28: Amber | E28: Planned finish within the next 14 days
A29: Indicator | B29: Value | D29: Red | E29: Planned finish in the past and not completed
A30: Records total | B30: =COUNTIF('Risks Issues Decisions'!$A$6:$A$35,"?*") | D30: Not Planned | E30: No start or finish date entered yet
A31: Open risks | B31: =COUNTIFS('Risks Issues Decisions'!$B$6:$B$35,"Risk",'Risks Issues Decisions'!$K$6:$K$35,"Open")
A32: Open issues | B32: =COUNTIFS('Risks Issues Decisions'!$B$6:$B$35,"Issue",'Risks Issues Decisions'!$K$6:$K$35,"Open")
A33: High severity, not closed | B33: =COUNTIFS('Risks Issues Decisions'!$G$6:$G$35,"High",'Risks Issues Decisions'!$K$6:$K$35,"<>Closed")
A34: Escalation needed | B34: =COUNTIF('Risks Issues Decisions'!$L$6:$L$35,"Yes")
A35: Overdue actions | B35: =COUNTIF('Risks Issues Decisions'!$N$6:$N$35,"Overdue")

Sheet Gantt
A1: NIS2 Group Implementation Project
A2: Gantt Chart (Weekly)
A3: Automatically derived from the Master Plan. Bars follow planned start and finish; the current week is highlighted.
I4: Oct 26 | M4: Nov 26 | R4: Dec 26 | V4: Jan 27 | Z4: Feb 27 | AD4: Mar 27 | AI4: Apr 27 | AM4: May 27 | AR4: Jun 27 | AV4: Jul 27 | AZ4: Aug 27 | BE4: Sep 27 | BI4: Oct 27 | BM4: Nov 27
A5: ID | B5: Phase | C5: Activity | D5: Start | E5: Finish | F5: Status | G5: 46286 | H5: 46293 | I5: 46300 | J5: 46307 | K5: 46314 | L5: 46321 | M5: 46328 | N5: 46335 | O5: 46342 | P5: 46349 | Q5: 46356 | R5: 46363 | S5: 46370 | T5: 46377 | U5: 46384 | V5: 46391 | W5: 46398 | X5: 46405 | Y5: 46412 | Z5: 46419 | AA5: 46426 | AB5: 46433 | AC5: 46440 | AD5: 46447 | AE5: 46454 | AF5: 46461 | AG5: 46468 | AH5: 46475 | AI5: 46482 | AJ5: 46489 | AK5: 46496 | AL5: 46503 | AM5: 46510 | AN5: 46517 | AO5: 46524 | AP5: 46531 | AQ5: 46538 | AR5: 46545 | AS5: 46552 | AT5: 46559 | AU5: 46566 | AV5: 46573 | AW5: 46580 | AX5: 46587 | AY5: 46594 | AZ5: 46601 | BA5: 46608 | BB5: 46615 | BC5: 46622 | BD5: 46629 | BE5: 46636 | BF5: 46643 | BG5: 46650 | BH5: 46657 | BI5: 46664 | BJ5: 46671 | BK5: 46678 | BL5: 46685 | BM5: 46692 | BN5: 46699 | BO5: 46706 | BP5: 46713 | BQ5: 46720
A6: ='Master Plan'!A6 | B6: ='Master Plan'!B6 | C6: ='Master Plan'!C6 | D6: ='Master Plan'!F6 | E6: ='Master Plan'!G6 | F6: ='Master Plan'!M6
A7: ='Master Plan'!A7 | B7: ='Master Plan'!B7 | C7: ='Master Plan'!C7 | D7: ='Master Plan'!F7 | E7: ='Master Plan'!G7 | F7: ='Master Plan'!M7
A8: ='Master Plan'!A8 | B8: ='Master Plan'!B8 | C8: ='Master Plan'!C8 | D8: ='Master Plan'!F8 | E8: ='Master Plan'!G8 | F8: ='Master Plan'!M8
A9: ='Master Plan'!A9 | B9: ='Master Plan'!B9 | C9: ='Master Plan'!C9 | D9: ='Master Plan'!F9 | E9: ='Master Plan'!G9 | F9: ='Master Plan'!M9
A10: ='Master Plan'!A10 | B10: ='Master Plan'!B10 | C10: ='Master Plan'!C10 | D10: ='Master Plan'!F10 | E10: ='Master Plan'!G10 | F10: ='Master Plan'!M10
A11: ='Master Plan'!A11 | B11: ='Master Plan'!B11 | C11: ='Master Plan'!C11 | D11: ='Master Plan'!F11 | E11: ='Master Plan'!G11 | F11: ='Master Plan'!M11
A12: ='Master Plan'!A12 | B12: ='Master Plan'!B12 | C12: ='Master Plan'!C12 | D12: ='Master Plan'!F12 | E12: ='Master Plan'!G12 | F12: ='Master Plan'!M12
A13: ='Master Plan'!A13 | B13: ='Master Plan'!B13 | C13: ='Master Plan'!C13 | D13: ='Master Plan'!F13 | E13: ='Master Plan'!G13 | F13: ='Master Plan'!M13
A14: ='Master Plan'!A14 | B14: ='Master Plan'!B14 | C14: ='Master Plan'!C14 | D14: ='Master Plan'!F14 | E14: ='Master Plan'!G14 | F14: ='Master Plan'!M14
A15: ='Master Plan'!A15 | B15: ='Master Plan'!B15 | C15: ='Master Plan'!C15 | D15: ='Master Plan'!F15 | E15: ='Master Plan'!G15 | F15: ='Master Plan'!M15
A16: ='Master Plan'!A16 | B16: ='Master Plan'!B16 | C16: ='Master Plan'!C16 | D16: ='Master Plan'!F16 | E16: ='Master Plan'!G16 | F16: ='Master Plan'!M16
A17: ='Master Plan'!A17 | B17: ='Master Plan'!B17 | C17: ='Master Plan'!C17 | D17: ='Master Plan'!F17 | E17: ='Master Plan'!G17 | F17: ='Master Plan'!M17
... A40: ='Master Plan'!A40 | B40: ='Master Plan'!B40 | C40: ='Master Plan'!C40 | D40: ='Master Plan'!F40 | E40: ='Master Plan'!G40 | F40: ='Master Plan'!M40

Sheet Master Plan
A1: NIS2 Group Implementation Project
A2: Master Plan
A3: Blue columns are formulas and locked. Gate dates are maintained on the Governance and Gates sheet and pulled in automatically.
A5: ID | B5: Phase | C5: Activity | D5: Primary Owner | E5: Support | F5: Planned Start | G5: Planned Finish | H5: Duration (Weeks) | I5: Dependency | J5: Deliverable / Exit Criterion | K5: Gate | L5: Gate Date | M5: Status | N5: Priority | O5: Progress % | P5: Schedule Status
A6: P1.1 | B6: 1. Initiation | C6: Prepare project kick-off and confirm participants | D6: Information Security Officer | E6: IT Coordinator; DPO | F6: 46286 | G6: 46290 | H6: =IF(OR(F6="",G6=""),"",ROUNDUP((G6-F6+1)/7,0)) | I6: None | J6: Kick-off agenda and participant list available | L6: =IF(K6="","",IFERROR(INDEX('Governance and Gates'!$B$6:$B$11,MATCH(K6,'Governance and Gates'!$A$6:$A$11,0)),"")) | M6: Not Started | N6: High | O6: 0 | P6: =IF(M6="Completed","Green",IF(OR(F6="",G6=""),"Not Planned",IF(TODAY()>G6,"Red",IF(TODAY()+14>G6,"Amber","Green"))))
A7: P1.2 | B7: 1. Initiation | C7: Conduct project kick-off | D7: Information Security Officer | E7: All project roles | F7: 46293 | G7: 46297 | H7: =IF(OR(F7="",G7=""),"",ROUNDUP((G7-F7+1)/7,0)) | I7: P1.1 | J7: Scope, approach, roles and meeting cadence communicated | L7: =IF(K7="","",IFERROR(INDEX('Governance and Gates'!$B$6:$B$11,MATCH(K7,'Governance and Gates'!$A$6:$A$11,0)),"")) | M7: Not Started | N7: High | O7: 0 | P7: =IF(M7="Completed","Green",IF(OR(F7="",G7=""),"Not Planned",IF(TODAY()>G7,"Red",IF(TODAY()+14>G7,"Amber","Green"))))
A8: P1.3 | B8: 1. Initiation | C8: Confirm project charter, governance and escalation route | D8: Information Security Officer | E8: Management Board; IT Coordinator; DPO | F8: 46300 | G8: 46311 | H8: =IF(OR(F8="",G8=""),"",ROUNDUP((G8-F8+1)/7,0)) | I8: P1.2 | J8: Project charter approved | K8: Gate 1 | L8: =IF(K8="","",IFERROR(INDEX('Governance and Gates'!$B$6:$B$11,MATCH(K8,'Governance and Gates'!$A$6:$A$11,0)),"")) | M8: Not Started | N8: High | O8: 0 | P8: =IF(M8="Completed","Green",IF(OR(F8="",G8=""),"Not Planned",IF(TODAY()>G8,"Red",IF(TODAY()+14>G8,"Amber","Green"))))
A9: P1.4 | B9: 1. Initiation | C9: Confirm assessment method, scope conventions and evidence-request process | D9: Information Security Officer | E9: IT; OT; DPO; advisers | F9: 46300 | G9: 46311 | H9: =IF(OR(F9="",G9=""),"",ROUNDUP((G9-F9+1)/7,0)) | I9: P1.2 | J9: Assessment method approved, including the handling of requirements operated centrally at HQ and the evidence-request process | K9: Gate 1 | L9: =IF(K9="","",IFERROR(INDEX('Governance and Gates'!$B$6:$B$11,MATCH(K9,'Governance and Gates'!$A$6:$A$11,0)),"")) | M9: Not Started | N9: High | O9: 0 | P9: =IF(M9="Completed","Green",IF(OR(F9="",G9=""),"Not Planned",IF(TODAY()>G9,"Red",IF(TODAY()+14>G9,"Amber","Green"))))
A10: P1.5 | B10: 1. Initiation | C10: Confirm assessment benchmark, chapter target levels and scoring model | D10: Information Security Officer | E10: Management Board; IT Coordinator; DE Adviser | F10: 46300 | G10: 46311 | H10: =IF(OR(F10="",G10=""),"",ROUNDUP((G10-F10+1)/7,0)) | I10: P1.2 | J10: Management Board confirms Implementing Regulation (EU) 2024/2690 as the applied assessment benchmark; chapter target levels and the scoring model are approved and recorded | K10: Gate 1 | L10: =IF(K10="","",IFERROR(INDEX('Governance and Gates'!$B$6:$B$11,MATCH(K10,'Governance and Gates'!$A$6:$A$11,0)),"")) | M10: Not Started | N10: High | O10: 0 | P10: =IF(M10="Completed","Green",IF(OR(F10="",G10=""),"Not Planned",IF(TODAY()>G10,"Red",IF(TODAY()+14>G10,"Amber","Green"))))
A11: P2.1 | B11: 2. Assessment Preparation | C11: Populate entity master data, contacts, applicability and central-HQ scope | D11: Information Security Officer | E11: Local Contacts; HR; IT | F11: 46307 | G11: 46325 | H11: =IF(OR(F11="",G11=""),"",ROUNDUP((G11-F11+1)/7,0)) | I11: P1.2 | J11: Entity master data maintained in the GAP workbook; requirements operated centrally at HQ pre-scoped for each subsidiary | L11: =IF(K11="","",IFERROR(INDEX('Governance and Gates'!$B$6:$B$11,MATCH(K11,'Governance and Gates'!$A$6:$A$11,0)),"")) | M11: Not Started | N11: Medium | O11: 0 | P11: =IF(M11="Completed","Green",IF(OR(F11="",G11=""),"Not Planned",IF(TODAY()>G11,"Red",IF(TODAY()+14>G11,"Amber","Green"))))
A12: P2.2 | B12: 2. Assessment Preparation | C12: Issue evidence and interview request for every entity | D12: Information Security Officer | E12: Central IT; Local IT; MSP+IT; OT; HR; Procurement; DPO; Advisers; Local Contact | F12: 46314 | G12: 46339 | H12: =IF(OR(F12="",G12=""),"",ROUNDUP((G12-F12+1)/7,0)) | I12: P1.4 | J12: Evidence request issued and interview participants confirmed | L12: =IF(K12="","",IFERROR(INDEX('Governance and Gates'!$B$6:$B$11,MATCH(K12,'Governance and Gates'!$A$6:$A$11,0)),"")) | M12: Not Started | N12: High | O12: 0 | P12: =IF(M12="Completed","Green",IF(OR(F12="",G12=""),"Not Planned",IF(TODAY()>G12,"Red",IF(TODAY()+14>G12,"Amber","Green"))))
A13: P3.1 | B13: 3. GAP Assessments | C13: Conduct remote assessment for every entity (174 requirements) | D13: Information Security Officer | E13: Central IT; Local IT; MSP+IT; OT; HR; Procurement; DPO; Advisers; Local Contact | F13: 46328 | G13: 46430 | H13: =IF(OR(F13="",G13=""),"",ROUNDUP((G13-F13+1)/7,0)) | I13: P2.2 | J13: Questionnaire completed; initial gaps and evidence recorded | L13: =IF(K13="","",IFERROR(INDEX('Governance and Gates'!$B$6:$B$11,MATCH(K13,'Governance and Gates'!$A$6:$A$11,0)),"")) | M13: Not Started | N13: High | O13: 0 | P13: =IF(M13="Completed","Green",IF(OR(F13="",G13=""),"Not Planned",IF(TODAY()>G13,"Red",IF(TODAY()+14>G13,"Amber","Green"))))
A14: P3.2 | B14: 3. GAP Assessments | C14: Validate findings for every entity | D14: Information Security Officer | E14: Central IT; Local IT; MSP+IT; Advisers | F14: 46363 | G14: 46444 | H14: =IF(OR(F14="",G14=""),"",ROUNDUP((G14-F14+1)/7,0)) | I14: P3.1 | J14: Findings factually validated | L14: =IF(K14="","",IFERROR(INDEX('Governance and Gates'!$B$6:$B$11,MATCH(K14,'Governance and Gates'!$A$6:$A$11,0)),"")) | M14: Not Started | N14: High | O14: 0 | P14: =IF(M14="Completed","Green",IF(OR(F14="",G14=""),"Not Planned",IF(TODAY()>G14,"Red",IF(TODAY()+14>G14,"Amber","Green"))))
A15: P4.1 | B15: 4. Consolidation | C15: Consolidate validated findings across all entities | D15: Information Security Officer | E15: IT Coordinator; DPO | F15: 46447 | G15: 46465 | H15: =IF(OR(F15="",G15=""),"",ROUNDUP((G15-F15+1)/7,0)) | I15: P3.2 | J15: Consolidated finding register available | L15: =IF(K15="","",IFERROR(INDEX('Governance and Gates'!$B$6:$B$11,MATCH(K15,'Governance and Gates'!$A$6:$A$11,0)),"")) | M15: Not Started | N15: High | O15: 0 | P15: =IF(M15="Completed","Green",IF(OR(F15="",G15=""),"Not Planned",IF(TODAY()>G15,"Red",IF(TODAY()+14>G15,"Amber","Green"))))
A16: P4.2 | B16: 4. Consolidation | C16: Identify common HQ controls and entity-specific gaps | D16: Information Security Officer | E16: Central IT; Local IT; MSP+IT; Advisers | F16: 46454 | G16: 46472 | H16: =IF(OR(F16="",G16=""),"",ROUNDUP((G16-F16+1)/7,0)) | I16: P4.1 | J16: Findings grouped into central and local treatment paths | L16: =IF(K16="","",IFERROR(INDEX('Governance and Gates'!$B$6:$B$11,MATCH(K16,'Governance and Gates'!$A$6:$A$11,0)),"")) | M16: Not Started | N16: High | O16: 0 | P16: =IF(M16="Completed","Green",IF(OR(F16="",G16=""),"Not Planned",IF(TODAY()>G16,"Red",IF(TODAY()+14>G16,"Amber","Green"))))
A17: P4.3 | B17: 4. Consolidation | C17: Define proposed work packages and acceptance criteria | D17: Information Security Officer | E17: Work-Package Owners | F17: 46468 | G17: 46486 | H17: =IF(OR(F17="",G17=""),"",ROUNDUP((G17-F17+1)/7,0)) | I17: P4.2 | J17: Proposed portfolio with owners and acceptance criteria | L17: =IF(K17="","",IFERROR(INDEX('Governance and Gates'!$B$6:$B$11,MATCH(K17,'Governance and Gates'!$A$6:$A$11,0)),"")) | M17: Not Started | N17: High | O17: 0 | P17: =IF(M17="Completed","Green",IF(OR(F17="",G17=""),"Not Planned",IF(TODAY()>G17,"Red",IF(TODAY()+14>G17,"Amber","Green"))))
A18: P4.4 | B18: 4. Consolidation | C18: Prioritise portfolio using High, Medium and Low ratings | D18: Information Security Officer | E18: IT Coordinator; DPO; Work-Package Owners | F18: 46483 | G18: 46493 | H18: =IF(OR(F18="",G18=""),"",ROUNDUP((G18-F18+1)/7,0)) | I18: P4.3 | J18: Prioritised work-package portfolio | L18: =IF(K18="","",IFERROR(INDEX('Governance and Gates'!$B$6:$B$11,MATCH(K18,'Governance and Gates'!$A$6:$A$11,0)),"")) | M18: Not Started | N18: High | O18: 0 | P18: =IF(M18="Completed","Green",IF(OR(F18="",G18=""),"Not Planned",IF(TODAY()>G18,"Red",IF(TODAY()+14>G18,"Amber","Green"))))
A19: P4.5 | B19: 4. Consolidation | C19: Present findings and recommendations to Management Board | D19: Information Security Officer | E19: IT Coordinator; DPO | F19: 46496 | G19: 46507 | H19: =IF(OR(F19="",G19=""),"",ROUNDUP((G19-F19+1)/7,0)) | I19: P4.4 | J19: Findings, recommendations and resource needs presented | K19: Gate 2 | L19: =IF(K19="","",IFERROR(INDEX('Governance and Gates'!$B$6:$B$11,MATCH(K19,'Governance and Gates'!$A$6:$A$11,0)),"")) | M19: Not Started | N19: High | O19: 0 | P19: =IF(M19="Completed","Green",IF(OR(F19="",G19=""),"Not Planned",IF(TODAY()>G19,"Red",IF(TODAY()+14>G19,"Amber","Green"))))
A20: P4.6 | B20: 4. Consolidation | C20: Approve scope, priorities, owners and risk-treatment approach | D20: Management Board | E20: Information Security Officer; IT Coordinator; DPO | F20: 46510 | G20: 46521 | H20: =IF(OR(F20="",G20=""),"",ROUNDUP((G20-F20+1)/7,0)) | I20: P4.5 | J20: Approved remediation portfolio and authorised resources | K20: Gate 3 | L20: =IF(K20="","",IFERROR(INDEX('Governance and Gates'!$B$6:$B$11,MATCH(K20,'Governance and Gates'!$A$6:$A$11,0)),"")) | M20: Not Started | N20: High | O20: 0 | P20: =IF(M20="Completed","Green",IF(OR(F20="",G20=""),"Not Planned",IF(TODAY()>G20,"Red",IF(TODAY()+14>G20,"Amber","Green"))))
A21: P5.1 | B21: 5. Remediation | C21: Launch approved High-priority work packages | D21: Assigned Work-Package Owners | E21: Relevant project roles | F21: 46524 | G21: 46535 | H21: =IF(OR(F21="",G21=""),"",ROUNDUP((G21-F21+1)/7,0)) | I21: P4.6 | J21: High-priority packages initiated | L21: =IF(K21="","",IFERROR(INDEX('Governance and Gates'!$B$6:$B$11,MATCH(K21,'Governance and Gates'!$A$6:$A$11,0)),"")) | M21: Not Started | N21: High | O21: 0 | P21: =IF(M21="Completed","Green",IF(OR(F21="",G21=""),"Not Planned",IF(TODAY()>G21,"Red",IF(TODAY()+14>G21,"Amber","Green"))))
A22: P5.2 | B22: 5. Remediation | C22: Implement High-priority and cross-entity HQ measures | D22: Assigned Work-Package Owners | E22: Central IT; Local IT; OT; HR; Procurement; DPO; MSP+IT | F22: 46531 | G22: 46630 | H22: =IF(OR(F22="",G22=""),"",ROUNDUP((G22-F22+1)/7,0)) | I22: P5.1 | J22: Approved High-priority measures completed or escalated | K22: Gate 4 | L22: =IF(K22="","",IFERROR(INDEX('Governance and Gates'!$B$6:$B$11,MATCH(K22,'Governance and Gates'!$A$6:$A$11,0)),"")) | M22: Not Started | N22: High | O22: 0 | P22: =IF(M22="Completed","Green",IF(OR(F22="",G22=""),"Not Planned",IF(TODAY()>G22,"Red",IF(TODAY()+14>G22,"Amber","Green"))))
A23: P5.3 | B23: 5. Remediation | C23: Implement Medium-priority measures | D23: Assigned Work-Package Owners | E23: Relevant project roles | F23: 46559 | G23: 46660 | H23: =IF(OR(F23="",G23=""),"",ROUNDUP((G23-F23+1)/7,0)) | I23: P5.1 | J23: Approved Medium-priority measures completed or escalated | L23: =IF(K23="","",IFERROR(INDEX('Governance and Gates'!$B$6:$B$11,MATCH(K23,'Governance and Gates'!$A$6:$A$11,0)),"")) | M23: Not Started | N23: Medium | O23: 0 | P23: =IF(M23="Completed","Green",IF(OR(F23="",G23=""),"Not Planned",IF(TODAY()>G23,"Red",IF(TODAY()+14>G23,"Amber","Green"))))
A24: P5.4 | B24: 5. Remediation | C24: Implement Low-priority measures required for project completion | D24: Assigned Work-Package Owners | E24: Relevant project roles | F24: 46587 | G24: 46675 | H24: =IF(OR(F24="",G24=""),"",ROUNDUP((G24-F24+1)/7,0)) | I24: P5.1 | J24: Required Low-priority measures completed, deferred or accepted | L24: =IF(K24="","",IFERROR(INDEX('Governance and Gates'!$B$6:$B$11,MATCH(K24,'Governance and Gates'!$A$6:$A$11,0)),"")) | M24: Not Started | N24: Low | O24: 0 | P24: =IF(M24="Completed","Green",IF(OR(F24="",G24=""),"Not Planned",IF(TODAY()>G24,"Red",IF(TODAY()+14>G24,"Amber","Green"))))
A25: P5.5 | B25: 5. Remediation | C25: Maintain implementation evidence and update GAP responses | D25: Information Security Officer | E25: Work-Package Owners | F25: 46531 | G25: 46675 | H25: =IF(OR(F25="",G25=""),"",ROUNDUP((G25-F25+1)/7,0)) | I25: P5.1 | J25: GAP workbook and evidence references kept current | L25: =IF(K25="","",IFERROR(INDEX('Governance and Gates'!$B$6:$B$11,MATCH(K25,'Governance and Gates'!$A$6:$A$11,0)),"")) | M25: Not Started | N25: High | O25: 0 | P25: =IF(M25="Completed","Green",IF(OR(F25="",G25=""),"Not Planned",IF(TODAY()>G25,"Red",IF(TODAY()+14>G25,"Amber","Green"))))
A26: P5.6 | B26: 5. Remediation | C26: Escalate blocked measures and unresolved resource decisions | D26: Information Security Officer | E26: IT Coordinator; DPO; Management Board | F26: 46531 | G26: 46675 | H26: =IF(OR(F26="",G26=""),"",ROUNDUP((G26-F26+1)/7,0)) | I26: P5.1 | J26: Material blockers resolved or formally accepted | K26: Gate 5 | L26: =IF(K26="","",IFERROR(INDEX('Governance and Gates'!$B$6:$B$11,MATCH(K26,'Governance and Gates'!$A$6:$A$11,0)),"")) | M26: Not Started | N26: High | O26: 0 | P26: =IF(M26="Completed","Green",IF(OR(F26="",G26=""),"Not Planned",IF(TODAY()>G26,"Red",IF(TODAY()+14>G26,"Amber","Green"))))
A27: P6.1 | B27: 6. Verification | C27: Review completion evidence against acceptance criteria | D27: Information Security Officer | E27: Work-Package Owners; Advisers | F27: 46631 | G27: 46682 | H27: =IF(OR(F27="",G27=""),"",ROUNDUP((G27-F27+1)/7,0)) | I27: P5.2; P5.3 | J27: Evidence reviewed and remaining deficiencies recorded | L27: =IF(K27="","",IFERROR(INDEX('Governance and Gates'!$B$6:$B$11,MATCH(K27,'Governance and Gates'!$A$6:$A$11,0)),"")) | M27: Not Started | N27: High | O27: 0 | P27: =IF(M27="Completed","Green",IF(OR(F27="",G27=""),"Not Planned",IF(TODAY()>G27,"Red",IF(TODAY()+14>G27,"Amber","Green"))))
A28: P6.2 | B28: 6. Verification | C28: Perform proportionate effectiveness checks | D28: Information Security Officer | E28: IT; OT; DPO; MSP+IT; Advisers | F28: 46657 | G28: 46689 | H28: =IF(OR(F28="",G28=""),"",ROUNDUP((G28-F28+1)/7,0)) | I28: P6.1 | J28: Effectiveness status updated in GAP workbook | L28: =IF(K28="","",IFERROR(INDEX('Governance and Gates'!$B$6:$B$11,MATCH(K28,'Governance and Gates'!$A$6:$A$11,0)),"")) | M28: Not Started | N28: High | O28: 0 | P28: =IF(M28="Completed","Green",IF(OR(F28="",G28=""),"Not Planned",IF(TODAY()>G28,"Red",IF(TODAY()+14>G28,"Amber","Green"))))
A29: P6.3 | B29: 6. Verification | C29: Obtain formal acceptance of any residual risks | D29: Management Board | E29: Information Security Officer; Risk Owners | F29: 46692 | G29: 46703 | H29: =IF(OR(F29="",G29=""),"",ROUNDUP((G29-F29+1)/7,0)) | I29: P6.1; P6.2 | J29: Residual-risk decisions documented | K29: Gate 5 | L29: =IF(K29="","",IFERROR(INDEX('Governance and Gates'!$B$6:$B$11,MATCH(K29,'Governance and Gates'!$A$6:$A$11,0)),"")) | M29: Not Started | N29: High | O29: 0 | P29: =IF(M29="Completed","Green",IF(OR(F29="",G29=""),"Not Planned",IF(TODAY()>G29,"Red",IF(TODAY()+14>G29,"Amber","Green"))))
A30: P6.4 | B30: 6. Verification | C30: Prepare project closure report and operational handover | D30: Information Security Officer | E30: IT Coordinator; DPO; Work-Package Owners | F30: 46699 | G30: 46710 | H30: =IF(OR(F30="",G30=""),"",ROUNDUP((G30-F30+1)/7,0)) | I30: P6.2; P6.3 | J30: Closure report and ongoing control owners confirmed | L30: =IF(K30="","",IFERROR(INDEX('Governance and Gates'!$B$6:$B$11,MATCH(K30,'Governance and Gates'!$A$6:$A$11,0)),"")) | M30: Not Started | N30: High | O30: 0 | P30: =IF(M30="Completed","Green",IF(OR(F30="",G30=""),"Not Planned",IF(TODAY()>G30,"Red",IF(TODAY()+14>G30,"Amber","Green"))))
A31: P6.5 | B31: 6. Verification | C31: Management review and formal project closure | D31: Management Board | E31: Information Security Officer; Steering Committee | F31: 46713 | G31: 46721 | H31: =IF(OR(F31="",G31=""),"",ROUNDUP((G31-F31+1)/7,0)) | I31: P6.4 | J31: Project closure approved; remaining activities transferred to operations | K31: Gate 6 | L31: =IF(K31="","",IFERROR(INDEX('Governance and Gates'!$B$6:$B$11,MATCH(K31,'Governance and Gates'!$A$6:$A$11,0)),"")) | M31: Not Started | N31: High | O31: 0 | P31: =IF(M31="Completed","Green",IF(OR(F31="",G31=""),"Not Planned",IF(TODAY()>G31,"Red",IF(TODAY()+14>G31,"Amber","Green"))))
H32: =IF(OR(F32="",G32=""),"",ROUNDUP((G32-F32+1)/7,0)) | L32: =IF(K32="","",IFERROR(INDEX('Governance and Gates'!$B$6:$B$11,MATCH(K32,'Governance and Gates'!$A$6:$A$11,0)),"")) | P32: =IF(M32="Completed","Green",IF(OR(F32="",G32=""),"Not Planned",IF(TODAY()>G32,"Red",IF(TODAY()+14>G32,"Amber","Green"))))
H33: =IF(OR(F33="",G33=""),"",ROUNDUP((G33-F33+1)/7,0)) | L33: =IF(K33="","",IFERROR(INDEX('Governance and Gates'!$B$6:$B$11,MATCH(K33,'Governance and Gates'!$A$6:$A$11,0)),"")) | P33: =IF(M33="Completed","Green",IF(OR(F33="",G33=""),"Not Planned",IF(TODAY()>G33,"Red",IF(TODAY()+14>G33,"Amber","Green"))))
H34: =IF(OR(F34="",G34=""),"",ROUNDUP((G34-F34+1)/7,0)) | L34: =IF(K34="","",IFERROR(INDEX('Governance and Gates'!$B$6:$B$11,MATCH(K34,'Governance and Gates'!$A$6:$A$11,0)),"")) | P34: =IF(M34="Completed","Green",IF(OR(F34="",G34=""),"Not Planned",IF(TODAY()>G34,"Red",IF(TODAY()+14>G34,"Amber","Green"))))
H35: =IF(OR(F35="",G35=""),"",ROUNDUP((G35-F35+1)/7,0)) | L35: =IF(K35="","",IFERROR(INDEX('Governance and Gates'!$B$6:$B$11,MATCH(K35,'Governance and Gates'!$A$6:$A$11,0)),"")) | P35: =IF(M35="Completed","Green",IF(OR(F35="",G35=""),"Not Planned",IF(TODAY()>G35,"Red",IF(TODAY()+14>G35,"Amber","Green"))))
H36: =IF(OR(F36="",G36=""),"",ROUNDUP((G36-F36+1)/7,0)) | L36: =IF(K36="","",IFERROR(INDEX('Governance and Gates'!$B$6:$B$11,MATCH(K36,'Governance and Gates'!$A$6:$A$11,0)),"")) | P36: =IF(M36="Completed","Green",IF(OR(F36="",G36=""),"Not Planned",IF(TODAY()>G36,"Red",IF(TODAY()+14>G36,"Amber","Green"))))
H37: =IF(OR(F37="",G37=""),"",ROUNDUP((G37-F37+1)/7,0)) | L37: =IF(K37="","",IFERROR(INDEX('Governance and Gates'!$B$6:$B$11,MATCH(K37,'Governance and Gates'!$A$6:$A$11,0)),"")) | P37: =IF(M37="Completed","Green",IF(OR(F37="",G37=""),"Not Planned",IF(TODAY()>G37,"Red",IF(TODAY()+14>G37,"Amber","Green"))))
H38: =IF(OR(F38="",G38=""),"",ROUNDUP((G38-F38+1)/7,0)) | L38: =IF(K38="","",IFERROR(INDEX('Governance and Gates'!$B$6:$B$11,MATCH(K38,'Governance and Gates'!$A$6:$A$11,0)),"")) | P38: =IF(M38="Completed","Green",IF(OR(F38="",G38=""),"Not Planned",IF(TODAY()>G38,"Red",IF(TODAY()+14>G38,"Amber","Green"))))
H39: =IF(OR(F39="",G39=""),"",ROUNDUP((G39-F39+1)/7,0)) | L39: =IF(K39="","",IFERROR(INDEX('Governance and Gates'!$B$6:$B$11,MATCH(K39,'Governance and Gates'!$A$6:$A$11,0)),"")) | P39: =IF(M39="Completed","Green",IF(OR(F39="",G39=""),"Not Planned",IF(TODAY()>G39,"Red",IF(TODAY()+14>G39,"Amber","Green"))))
H40: =IF(OR(F40="",G40=""),"",ROUNDUP((G40-F40+1)/7,0)) | L40: =IF(K40="","",IFERROR(INDEX('Governance and Gates'!$B$6:$B$11,MATCH(K40,'Governance and Gates'!$A$6:$A$11,0)),"")) | P40: =IF(M40="Completed","Green",IF(OR(F40="",G40=""),"Not Planned",IF(TODAY()>G40,"Red",IF(TODAY()+14>G40,"Amber","Green"))))

Sheet Work Packages
A1: NIS2 Group Implementation Project
A2: Work Packages
A3: Create work packages only after finding validation and management approval (Gate 3). The WP ID is generated automatically as soon as a work package description is entered.
A5: WP ID | B5: GAP Finding ID | C5: Entity | D5: Measure Area | E5: Work Package | F5: Central or Local | G5: Priority | H5: Owner | I5: Planned Start | J5: Planned Finish | K5: Acceptance Criterion | L5: Expected Evidence | M5: Dependency | N5: Status | O5: Progress % | P5: Schedule Status | Q5: Comments
A6: =IF($E6="","","WP-"&TEXT(ROW()-5,"000")) | P6: =IF($E6="","",IF(N6="Completed","Green",IF(OR(I6="",J6=""),"Not Planned",IF(TODAY()>J6,"Red",IF(TODAY()+14>J6,"Amber","Green")))))
A7: =IF($E7="","","WP-"&TEXT(ROW()-5,"000")) | P7: =IF($E7="","",IF(N7="Completed","Green",IF(OR(I7="",J7=""),"Not Planned",IF(TODAY()>J7,"Red",IF(TODAY()+14>J7,"Amber","Green")))))
A8: =IF($E8="","","WP-"&TEXT(ROW()-5,"000")) | P8: =IF($E8="","",IF(N8="Completed","Green",IF(OR(I8="",J8=""),"Not Planned",IF(TODAY()>J8,"Red",IF(TODAY()+14>J8,"Amber","Green")))))
A9: =IF($E9="","","WP-"&TEXT(ROW()-5,"000")) | P9: =IF($E9="","",IF(N9="Completed","Green",IF(OR(I9="",J9=""),"Not Planned",IF(TODAY()>J9,"Red",IF(TODAY()+14>J9,"Amber","Green")))))
A10: =IF($E10="","","WP-"&TEXT(ROW()-5,"000")) | P10: =IF($E10="","",IF(N10="Completed","Green",IF(OR(I10="",J10=""),"Not Planned",IF(TODAY()>J10,"Red",IF(TODAY()+14>J10,"Amber","Green")))))
A11: =IF($E11="","","WP-"&TEXT(ROW()-5,"000")) | P11: =IF($E11="","",IF(N11="Completed","Green",IF(OR(I11="",J11=""),"Not Planned",IF(TODAY()>J11,"Red",IF(TODAY()+14>J11,"Amber","Green")))))
A12: =IF($E12="","","WP-"&TEXT(ROW()-5,"000")) | P12: =IF($E12="","",IF(N12="Completed","Green",IF(OR(I12="",J12=""),"Not Planned",IF(TODAY()>J12,"Red",IF(TODAY()+14>J12,"Amber","Green")))))
A13: =IF($E13="","","WP-"&TEXT(ROW()-5,"000")) | P13: =IF($E13="","",IF(N13="Completed","Green",IF(OR(I13="",J13=""),"Not Planned",IF(TODAY()>J13,"Red",IF(TODAY()+14>J13,"Amber","Green")))))
A14: =IF($E14="","","WP-"&TEXT(ROW()-5,"000")) | P14: =IF($E14="","",IF(N14="Completed","Green",IF(OR(I14="",J14=""),"Not Planned",IF(TODAY()>J14,"Red",IF(TODAY()+14>J14,"Amber","Green")))))
A15: =IF($E15="","","WP-"&TEXT(ROW()-5,"000")) | P15: =IF($E15="","",IF(N15="Completed","Green",IF(OR(I15="",J15=""),"Not Planned",IF(TODAY()>J15,"Red",IF(TODAY()+14>J15,"Amber","Green")))))
A16: =IF($E16="","","WP-"&TEXT(ROW()-5,"000")) | P16: =IF($E16="","",IF(N16="Completed","Green",IF(OR(I16="",J16=""),"Not Planned",IF(TODAY()>J16,"Red",IF(TODAY()+14>J16,"Amber","Green")))))
A17: =IF($E17="","","WP-"&TEXT(ROW()-5,"000")) | P17: =IF($E17="","",IF(N17="Completed","Green",IF(OR(I17="",J17=""),"Not Planned",IF(TODAY()>J17,"Red",IF(TODAY()+14>J17,"Amber","Green")))))
... A45: =IF($E45="","","WP-"&TEXT(ROW()-5,"000")) | P45: =IF($E45="","",IF(N45="Completed","Green",IF(OR(I45="",J45=""),"Not Planned",IF(TODAY()>J45,"Red",IF(TODAY()+14>J45,"Amber","Green")))))

Sheet Governance and Gates
A1: NIS2 Group Implementation Project
A2: Governance, Gates and RACI
A3: Gate dates are maintained here only; the Master Plan reads them automatically.
A5: Gate | B5: Planned Date | C5: Decision | D5: Decision Owner | E5: Required Input | F5: Approval Criterion | G5: Status | H5: Decision Reference | I5: Activities | J5: Open Activities
A6: Gate 1 | B6: 46311 | C6: Approve project charter, assessment method, benchmark and target levels | D6: Management Board | E6: Scope; roles; schedule; assessment method; applied benchmark; chapter target levels | F6: Scope and responsibilities confirmed; required participants available; benchmark and target levels recorded as a management decision | G6: Not Started | I6: =COUNTIF('Master Plan'!$K$6:$K$40,$A6) | J6: =COUNTIFS('Master Plan'!$K$6:$K$40,$A6,'Master Plan'!$M$6:$M$40,"<>Completed")
A7: Gate 2 | B7: 46507 | C7: Accept consolidated GAP findings | D7: Management Board | E7: Validated findings; legal input; cross-entity analysis | F7: Material findings are complete, understandable and supported by evidence | G7: Not Started | I7: =COUNTIF('Master Plan'!$K$6:$K$40,$A7) | J7: =COUNTIFS('Master Plan'!$K$6:$K$40,$A7,'Master Plan'!$M$6:$M$40,"<>Completed")
A8: Gate 3 | B8: 46521 | C8: Approve remediation portfolio and resources | D8: Management Board | E8: Proposed work packages; priorities; ownership; resource needs | F8: High-priority and reusable central measures funded and assigned | G8: Not Started | I8: =COUNTIF('Master Plan'!$K$6:$K$40,$A8) | J8: =COUNTIFS('Master Plan'!$K$6:$K$40,$A8,'Master Plan'!$M$6:$M$40,"<>Completed")
A9: Gate 4 | B9: 46630 | C9: Review High-priority implementation | D9: Steering Committee | E9: Work-package status; evidence; blockers; overdue actions | F9: High-priority measures completed or supported by approved recovery plans | G9: Not Started | I9: =COUNTIF('Master Plan'!$K$6:$K$40,$A9) | J9: =COUNTIFS('Master Plan'!$K$6:$K$40,$A9,'Master Plan'!$M$6:$M$40,"<>Completed")
A10: Gate 5 | B10: 46703 | C10: Accept residual risks and unresolved exceptions | D10: Management Board | E10: Effectiveness results; unresolved gaps; risk recommendations | F10: Residual risks have named owners and documented decisions | G10: Not Started | I10: =COUNTIF('Master Plan'!$K$6:$K$40,$A10) | J10: =COUNTIFS('Master Plan'!$K$6:$K$40,$A10,'Master Plan'!$M$6:$M$40,"<>Completed")
A11: Gate 6 | B11: 46721 | C11: Close project and transfer controls to operations | D11: Management Board | E11: Closure report; evidence status; ongoing ownership | F11: NIS2 measures implemented, verified or formally accepted | G11: Not Started | I11: =COUNTIF('Master Plan'!$K$6:$K$40,$A11) | J11: =COUNTIFS('Master Plan'!$K$6:$K$40,$A11,'Master Plan'!$M$6:$M$40,"<>Completed")
A14: RACI Matrix
A15: Activity | B15: Management Board | C15: Information Security Officer | D15: IT Coordinator | E15: Central IT | F15: Local IT / MSP | G15: DPO | H15: HR | I15: IT Procurement | J15: OT | K15: DE Adviser | L15: NL Adviser
A16: Project charter and scope | B16: A | C16: R | D16: C | E16: I | F16: I | G16: C | H16: I | I16: I | J16: I | K16: C | L16: C
A17: Assessment method | B17: I | C17: A/R | D17: C | E17: C | F17: C | G17: C | H17: I | I17: I | J17: C | K17: C | L17: C
A18: Evidence collection | B18: I | C18: A | D18: C | E18: R | F18: R | G18: R | H18: R | I18: R | J18: R | K18: C | L18: C
A19: Remote assessment interviews | B19: I | C19: A/R | D19: C | E19: R | F19: R | G19: R | H19: C | I19: C | J19: R | K19: C | L19: C
A20: Finding validation | B20: I | C20: A/R | D20: C | E20: R | F20: R | G20: C | H20: I | I20: I | J20: C | K20: C | L20: I
A21: Work-package design | B21: I | C21: A/R | D21: C | E21: R | F21: R | G21: C | H21: C | I21: C | J21: C | K21: C | L21: C
A22: Priority and budget approval | B22: A | C22: R | D22: C | E22: C | F22: C | G22: C | H22: I | I22: I | J22: I | K22: I | L22: I
A23: Technical implementation | B23: I | C23: C | D23: A | E23: R | F23: R | G23: I | H23: I | I23: C | J23: R | K23: I | L23: I
A24: Policy and process implementation | B24: I | C24: A/R | D24: C | E24: C | F24: C | G24: C | H24: C | I24: C | J24: C | K24: C | L24: C
A25: Supplier and MSP measures | B25: I | C25: C | D25: C | E25: C | F25: R | G25: C | H25: I | I25: A/R | J25: I | K25: I | L25: C
A26: Effectiveness review | B26: I | C26: A/R | D26: C | E26: R | F26: R | G26: C | H26: C | I26: C | J26: R | K26: C | L26: C
... A28: Project closure | B28: A | C28: R | D28: C | E28: I | F28: I | G28: C | H28: I | I28: I | J28: I | K28: I | L28: I
A32: Role Notes
A33: Role | B33: Planning Note
A34: Information Security Officer | B34: Overall project manager; prepares findings, recommendations and management decisions
A35: Management Board | B35: Sponsor; approves material expenditure, priorities, risk treatment and residual risks
A36: IT Coordinator | B36: Steering Committee member; coordinates technical ownership and dependencies
A37: Data Protection Officer | B37: Steering Committee member; advises on privacy-related incidents and controls
A38: German External Adviser | B38: Specialist support limited to approximately four hours per month
A39: Dutch External Adviser | B39: Supports Dutch legal interpretation, entity-specific obligations and finding validation
A40: Central IT | B40: Provides controls and evidence for HQ and for the subsidiaries that rely on central IT
A41: MSP | B41: Provides controls, evidence and remediation for subsidiaries without internal IT
A42: OT | B42: Owns or supports production and industrial-control-system requirements
A43: IT Procurement | B43: Supports supplier inventories, contractual requirements and MSP governance
A44: HR | B44: Supports personnel security, awareness, onboarding, role changes and offboarding

Sheet Risks Issues Decisions
A1: NIS2 Group Implementation Project
A2: Risks, Issues and Decisions
A3: One record per risk, issue or decision. Due Status is calculated automatically.
A5: Record ID | B5: Type | C5: Date Raised | D5: Description | E5: Impact | F5: Probability | G5: Severity | H5: Owner | I5: Mitigation / Required Action | J5: Target Date | K5: Status | L5: Escalation Needed | M5: Decision / Resolution | N5: Due Status
A6: R1 | B6: Risk | C6: 46272 | D6: Limited availability because project work is performed alongside normal operations | E6: High | F6: High | G6: High | H6: Information Security Officer | I6: Use phased assessments; restrict meetings; prioritise reusable HQ controls; escalate overdue High-priority tasks | J6: 46290 | K6: Open | L6: Yes | N6: =IF(OR($J6="",$A6=""),"",IF(OR($K6="Closed",$K6="Accepted"),"Closed",IF(TODAY()>$J6,"Overdue",IF(TODAY()+14>$J6,"Due soon","On track"))))
N7: =IF(OR($J7="",$A7=""),"",IF(OR($K7="Closed",$K7="Accepted"),"Closed",IF(TODAY()>$J7,"Overdue",IF(TODAY()+14>$J7,"Due soon","On track"))))
N8: =IF(OR($J8="",$A8=""),"",IF(OR($K8="Closed",$K8="Accepted"),"Closed",IF(TODAY()>$J8,"Overdue",IF(TODAY()+14>$J8,"Due soon","On track"))))
N9: =IF(OR($J9="",$A9=""),"",IF(OR($K9="Closed",$K9="Accepted"),"Closed",IF(TODAY()>$J9,"Overdue",IF(TODAY()+14>$J9,"Due soon","On track"))))
N10: =IF(OR($J10="",$A10=""),"",IF(OR($K10="Closed",$K10="Accepted"),"Closed",IF(TODAY()>$J10,"Overdue",IF(TODAY()+14>$J10,"Due soon","On track"))))
N11: =IF(OR($J11="",$A11=""),"",IF(OR($K11="Closed",$K11="Accepted"),"Closed",IF(TODAY()>$J11,"Overdue",IF(TODAY()+14>$J11,"Due soon","On track"))))
N12: =IF(OR($J12="",$A12=""),"",IF(OR($K12="Closed",$K12="Accepted"),"Closed",IF(TODAY()>$J12,"Overdue",IF(TODAY()+14>$J12,"Due soon","On track"))))
N13: =IF(OR($J13="",$A13=""),"",IF(OR($K13="Closed",$K13="Accepted"),"Closed",IF(TODAY()>$J13,"Overdue",IF(TODAY()+14>$J13,"Due soon","On track"))))
N14: =IF(OR($J14="",$A14=""),"",IF(OR($K14="Closed",$K14="Accepted"),"Closed",IF(TODAY()>$J14,"Overdue",IF(TODAY()+14>$J14,"Due soon","On track"))))
N15: =IF(OR($J15="",$A15=""),"",IF(OR($K15="Closed",$K15="Accepted"),"Closed",IF(TODAY()>$J15,"Overdue",IF(TODAY()+14>$J15,"Due soon","On track"))))
N16: =IF(OR($J16="",$A16=""),"",IF(OR($K16="Closed",$K16="Accepted"),"Closed",IF(TODAY()>$J16,"Overdue",IF(TODAY()+14>$J16,"Due soon","On track"))))
N17: =IF(OR($J17="",$A17=""),"",IF(OR($K17="Closed",$K17="Accepted"),"Closed",IF(TODAY()>$J17,"Overdue",IF(TODAY()+14>$J17,"Due soon","On track"))))
N18: =IF(OR($J18="",$A18=""),"",IF(OR($K18="Closed",$K18="Accepted"),"Closed",IF(TODAY()>$J18,"Overdue",IF(TODAY()+14>$J18,"Due soon","On track"))))
... N35: =IF(OR($J35="",$A35=""),"",IF(OR($K35="Closed",$K35="Accepted"),"Closed",IF(TODAY()>$J35,"Overdue",IF(TODAY()+14>$J35,"Due soon","On track"))))

Sheet Lists
A1: NIS2 Group Implementation Project
A2: Master Data and Picklists
A3: Single source for all drop-down lists. Add values at the end of a column and extend the named range.
A5: Status | B5: Priority | C5: Phase | D5: Gate | E5: Entity | F5: Owner / Role | G5: Central or Local | H5: Record Type | I5: Rating | J5: RACI | K5: Yes / No | L5: Measure Area | M5: Record Status
A6: Not Started | B6: High | C6: 1. Initiation | D6: Gate 1 | E6: Group / All Entities | F6: Information Security Officer | G6: Central | H6: Risk | I6: High | J6: R | K6: Yes | L6: Governance | M6: Open
A7: In Progress | B7: Medium | C7: 2. Assessment Preparation | D7: Gate 2 | F7: Management Board | G7: Local | H7: Issue | I7: Medium | J7: A | K7: No | L7: Risk Management | M7: In Progress
A8: Completed | B8: Low | C8: 3. GAP Assessments | D8: Gate 3 | F8: IT Coordinator | H8: Decision | I8: Low | J8: C | L8: Incident Handling and Reporting | M8: Closed
A9: Blocked | C9: 4. Consolidation | D9: Gate 4 | F9: Central IT | J9: I | L9: Business Continuity | M9: Accepted
A10: Deferred | C10: 5. Remediation | D10: Gate 5 | F10: Local IT | J10: A/R | L10: Supply Chain Security | M10: Escalated
A11: Cancelled | C11: 6. Verification | D11: Gate 6 | F11: MSP+IT | J11: - | L11: Access Control
F12: Data Protection Officer | L12: Asset Management
F13: HR | L13: Awareness and Training
F14: IT Procurement | L14: Cryptography
F15: OT | L15: Vulnerability Management
F16: German External Adviser | L16: Logging and Monitoring
F17: Dutch External Adviser | L17: Physical Security
F18: Assigned Work-Package Owners | L18: Supplier and MSP Governance

Sheet Instructions
A1: NIS2 Group Implementation Project
A2: Instructions and Planning Principles
A3: Reference sheet. It contains no project data and does not need to be maintained.
A5: How to Use This Workbook
A6: Sheet | B6: Purpose
A7: Dashboard | B7: Read-only overview. All figures are calculated from the other sheets.
A8: Project Overview | B8: Scope, roles, cadence and success criteria of the project.
A9: Master Plan | B9: The plan of record. Maintain status, priority and progress here.
A10: Gantt | B10: Read-only weekly bar chart derived from the Master Plan.
A11: Work Packages | B11: Remediation backlog. Populated only after Gate 3.
A12: Governance and Gates | B12: Gate dates and decisions, RACI matrix and role notes.
A13: Risks Issues Decisions | B13: Register for risks, issues and management decisions.
A14: Lists | B14: Master data behind every drop-down. Extend here, not in the tables.
A17: Editing Rules
A18: Rule | B18: Explanation
A19: White cells | B19: Input cells. Enter or change values here.
A20: Shaded formula columns | B20: Calculated and protected: Duration, Gate Date, Schedule Status, WP ID, Due Status and every figure on the Dashboard and Gantt sheet.
A21: Sheet protection | B21: Applied without a password. Review > Unprotect Sheet if a formula has to be changed.
A22: Drop-downs | B22: Status, priority, phase, gate, entity, owner and rating values come from the Lists sheet.
A23: Adding rows | B23: Type into the first empty row of a table; formulas and formatting extend automatically.
A24: New picklist values | B24: Add the value at the end of the column on the Lists sheet, then extend the named range under Formulas > Name Manager.
A25: Gate dates | B25: Maintain on the Governance and Gates sheet only. The Master Plan reads them automatically.
A26: Dates | B26: Enter as real dates in the format YYYY-MM-DD, never as text.
A29: Planning Principles
A30: Principle | B30: Application
A31: Keep project management proportionate | B31: Maintain only information required for decisions, ownership, deadlines and escalation
A32: Avoid duplicate records | B32: Detailed findings remain in the GAP Analysis workbook; this workbook references their Finding IDs
A33: Separate assessment from remediation | B33: Do not define detailed remediation work packages before the assessments are complete
A34: Prefer reusable group controls | B34: Prioritise central policies, processes and technical controls that cover several entities
A35: Preserve entity accountability | B35: Each legal entity must confirm local governance, reporting routes, responsibilities and applicability
A36: Use realistic deadlines | B36: Schedule work around operational commitments and limited external-adviser availability
A37: Document decisions | B37: Record scope decisions, risk acceptance, major changes and management approvals
A38: Verify completion | B38: A work package is complete only when its acceptance criterion and expected evidence are available
A41: Work Package Rules
A42: Rule | B42: Instruction
A43: Creation point | B43: Create work packages only after finding validation and management approval
A44: Finding link | B44: Copy the Finding ID from the final GAP Analysis Action Plan
A45: Central or Local | B45: Use Central where one HQ measure covers several entities; otherwise use Local
A46: Priority | B46: Use High, Medium or Low
A47: Acceptance criterion | B47: Describe the observable condition that must be satisfied before closure
...
